Workbook
Name EXCEL: IF([1]呈现!$D$2>0,[1]辅助!$A$1,IF([1]呈现!$D$2<0,[1]辅助!$A$2,[1]辅助!$A$3))
Name PPT: IF([1]呈现!$D$3>0,[1]辅助!$A$1,IF([1]呈现!$D$3<0,[1]辅助!$A$2,[1]辅助!$A$3))

Sheet 目标数据
A1: 骏延集团2026年每月新媒体目标数据
A2: 序号 | B2: 门店名称 | C2: 2026年5月新媒体目标数据
C3: 投流目标 | F3: 直播场次 目标 | G3: 短视频发布数目标 | H3: 线索目标
C4: 直播投流 目标 | D4: 短视频投流目标 | E4: 总投流 目标 | H4: 直播线索 目标 | I4: 直播场均线索目标 | J4: 短视频 线索目标 | K4: 短视频均条线索目标 | L4: 本地线索 目标 | M4: 总线索 目标 | N4: 厂家下发 | O4: 总到店 目标 | P4: 总订单 目标
A5: 1 | B5: 花都广本 | F5: 120 | G5: 100 | H5: 1000 | I5: =H5/F5 -> 8.3333333 | J5: 200 | K5: =J5/G5 -> 2 | L5: 1000 | M5: =H5+J5+N5 -> 1200 | N5: 0 | O5: 50 | P5: 25
A6: 2 | B6: 花都建设北零跑 | F6: 80 | G6: 90 | H6: 600 | I6: =H6/F6 -> 7.5 | J6: 800 | K6: =J6/G6 -> 8.8888889 | L6: 1200 | M6: =H6+J6+N6 -> 1400 | N6: 0 | O6: 80 | P6: 20
A7: 3 | B7: 白云零跑 | F7: 80 | G7: 80 | H7: 450 | I7: =H7/F7 -> 5.625 | J7: 150 | K7: =J7/G7 -> 1.875 | L7: 600 | M7: =H7+J7+N7 -> 600 | N7: 0 | O7: 60 | P7: 15
A8: 4 | B8: 花都传祺 | F8: 70 | G8: 70 | H8: 200 | I8: =H8/F8 -> 2.8571429 | J8: 50 | K8: =J8/G8 -> 0.71428571 | L8: 100 | M8: =H8+J8+N8 -> 250 | N8: 0 | O8: 30 | P8: 6
A9: 5 | B9: 清远极氪 | F9: 90 | G9: 60 | H9: 400 | I9: =H9/F9 -> 4.4444444 | J9: 50 | K9: =J9/G9 -> 0.83333333 | L9: 200 | M9: =H9+J9+N9 -> 450 | N9: 0 | O9: 40 | P9: 5
A10: 6 | B10: 清远广本 | F10: 70 | G10: 70 | H10: 200 | I10: =H10/F10 -> 2.8571429 | J10: 50 | K10: =J10/G10 -> 0.71428571 | L10: 30 | M10: =H10+J10+N10 -> 350 | N10: 100 | O10: 30 | P10: 8
A11: 7 | B11: 鑫海广本 | F11: 80 | G11: 60 | H11: 350 | I11: =H11/F11 -> 4.375 | J11: 60 | K11: =J11/G11 -> 1 | L11: 200 | M11: =H11+J11+N11 -> 510 | N11: 100 | O11: 45 | P11: 15
A12: 8 | B12: 汕头广本 | F12: 50 | G12: 80 | H12: 300 | I12: =H12/F12 -> 6 | J12: 400 | K12: =J12/G12 -> 5 | L12: 600 | M12: =H12+J12+N12 -> 700 | N12: 0 | O12: 40 | P12: 20
A13: 9 | B13: 江门大众 | F13: 60 | G13: 60 | H13: 120 | I13: =H13/F13 -> 2 | J13: 300 | K13: =J13/G13 -> 5 | L13: 200 | M13: =H13+J13+N13 -> 540 | N13: 120 | O13: 20 | P13: 10
A14: 10 | B14: 河源零跑 | F14: 80 | G14: 90 | H14: 600 | I14: =H14/F14 -> 7.5 | J14: 800 | K14: =J14/G14 -> 8.8888889 | L14: 1200 | M14: =H14+J14+N14 -> 1400 | N14: 0 | O14: 80 | P14: 20
A15: 11 | B15: 汕头零跑 | F15: 100 | G15: 100 | H15: 800 | I15: =H15/F15 -> 8 | J15: 600 | K15: =J15/G15 -> 6 | L15: 1200 | M15: =H15+J15+N15 -> 1400 | N15: 0 | O15: 80 | P15: 20
A16: 12 | B16: 清远港鸿 | F16: 80 | G16: 90 | H16: 200 | I16: =H16/F16 -> 2.5 | J16: 200 | K16: =J16/G16 -> 2.2222222 | L16: 150 | M16: =H16+J16+N16 -> 456 | N16: 56 | O16: 50 | P16: 8
... A21: 17 | B21: 北站店 | F21: 80 | G21: 100 | H21: 200 | I21: =H21/F21 -> 2.5 | J21: 200 | K21: =J21/G21 -> 2 | L21: 400 | M21: =H21+J21+N21 -> 400 | N21: 0 | O21: 20 | P21: 7
A22: 18 | B22: 清远智己 | F22: 40 | G22: 40 | H22: 30 | I22: =H22/F22 -> 0.75 | J22: 30 | K22: =J22/G22 -> 0.75 | L22: 250 | M22: 250 | N22: 0 | O22: 8 | P22: 2
B23: 合计 | F23: =SUM(F5:F22) -> 1380 | G23: =SUM(G5:G22) -> 1360 | H23: =SUM(H5:H22) -> 6480 | I23: =SUM(I5:I22) -> 78.242063 | J23: =SUM(J5:J22) -> 4320 | K23: =SUM(K5:K22) -> 51.94246 | L23: =SUM(L5:L22) -> 8550 | M23: =SUM(M5:M22) -> 11394 | ... P23: =SUM(P5:P22) -> 232

Sheet 核心指标进度表
A1: 骏延集团2026年5月新媒体运营核心指标
K2: 线索
A3: 统计周期： | B3: 5.1-5.24 | D3: 时间进度： | E3: =24/31*100% -> 0.77419355 | L3: 4.1-4.5 | M3: 4.6-4.12 | N3: 4.13-4.19 | O3: 4.20-4.30
A4: ='总表-数据收集'!B5 -> 花都广本 | I4: 5 | K4: 花都广本 | L4: ='总表-数据收集'!AI5 -> 3099 | M4: ='总表-数据收集'!BH5 -> 1529 | N4: ='总表-数据收集'!CG5 -> 1277 | O4: ='总表-数据收集'!DF5 -> 731
A5: KPI | B5: 本周 | C5: 月累 | D5: 目标 | E5: 达成率 | F5: 进度差异 | G5: 离目标差异 | H5: 周趋势 | K5: 花都建设北零跑 | L5: ='总表-数据收集'!AI6 -> 869 | M5: ='总表-数据收集'!BH6 -> 495 | N5: ='总表-数据收集'!CG6 -> 1446 | O5: ='总表-数据收集'!DF6 -> 1054
A6: 直播场次 | B6: =#REF! -> #REF! | C6: ='总表-数据收集'!F5 -> 853 | D6: =目标数据!F5 -> 120 | E6: =C6/D6 -> 7.1083333 | F6: =C6-D6*E3 -> 760.09677 | G6: =C6-D6 -> 733 | K6: 白云零跑 | L6: ='总表-数据收集'!AI7 -> 1160 | M6: ='总表-数据收集'!BH7 -> 681 | N6: ='总表-数据收集'!CG7 -> 902 | O6: ='总表-数据收集'!DF7 -> 1112
A7: 短视频发布数 | B7: =#REF! -> #REF! | C7: ='总表-数据收集'!G5 -> 1213 | D7: =目标数据!G5 -> 100 | E7: =C7/D7 -> 12.13 | F7: =C7-D7*E3 -> 1135.5806 | G7: =C7-D7 -> 1113 | K7: 花都传祺 | L7: ='总表-数据收集'!AI8 -> 579 | M7: ='总表-数据收集'!BH8 -> 302 | N7: ='总表-数据收集'!CG8 -> 870 | O7: ='总表-数据收集'!DF8 -> 557
A8: 总线索 | B8: =#REF! -> #REF! | C8: ='总表-数据收集'!H5 -> 8849 | D8: =目标数据!M5 -> 1200 | E8: =C8/D8 -> 7.3741667 | F8: =C8-D8*E3 -> 7919.9677 | G8: =C8-D8 -> 7649 | K8: 清远极氪 | L8: ='总表-数据收集'!AI9 -> 68 | M8: ='总表-数据收集'!BH9 -> 369 | N8: ='总表-数据收集'!CG9 -> 345 | O8: ='总表-数据收集'!DF9 -> 384
A9: 总到店 | B9: =#REF! -> #REF! | C9: ='总表-数据收集'!R5 -> 209 | D9: =目标数据!O5 -> 50 | E9: =C9/D9 -> 4.18 | F9: =C9-D9*E3 -> 170.29032 | G9: =C9-D9 -> 159 | K9: 清远广本 | L9: ='总表-数据收集'!AI10 -> 683 | M9: ='总表-数据收集'!BH10 -> 765 | N9: ='总表-数据收集'!CG10 -> 867 | O9: ='总表-数据收集'!DF10 -> 593
A10: 新媒体订单 | B10: =#REF! -> #REF! | C10: ='总表-数据收集'!U5 -> 83 | D10: =目标数据!P5 -> 25 | E10: =C10/D10 -> 3.32 | F10: =C10-D10*E3 -> 63.645161 | G10: =C10-D10 -> 58 | K10: 鑫海广本 | L10: ='总表-数据收集'!AI11 -> 502 | M10: ='总表-数据收集'!BH11 -> 181 | N10: ='总表-数据收集'!CG11 -> 394 | O10: ='总表-数据收集'!DF11 -> 316
A11: 新媒体订单占零售订单比例 | B11: ='总表-数据收集'!X5 -> 0.038 | K11: 汕头广本 | L11: ='总表-数据收集'!AI12 -> 0 | M11: ='总表-数据收集'!BH12 -> 0 | N11: ='总表-数据收集'!CG12 -> 461 | O11: ='总表-数据收集'!DF12 -> 497
A12: 厂家矩阵排名 | B12: ='总表-数据收集'!AC5 -> 77 | K12: 江门大众 | L12: ='总表-数据收集'!AI13 -> 343 | M12: ='总表-数据收集'!BH13 -> 351 | N12: ='总表-数据收集'!CG13 -> 471 | O12: ='总表-数据收集'!DF13 -> 324
K13: 河源零跑 | L13: ='总表-数据收集'!AI14 -> 467 | M13: ='总表-数据收集'!BH14 -> 671 | N13: ='总表-数据收集'!CG14 -> 1074 | O13: ='总表-数据收集'!DF14 -> 840
K14: 汕头零跑 | L14: ='总表-数据收集'!AI15 -> 593 | M14: ='总表-数据收集'!BH15 -> 461 | N14: ='总表-数据收集'!CG15 -> 1200 | O14: ='总表-数据收集'!DF15 -> 1337
K15: 清远港鸿 | L15: ='总表-数据收集'!AI16 -> 319 | M15: ='总表-数据收集'!BH16 -> 282 | N15: ='总表-数据收集'!CG16 -> 338 | O15: ='总表-数据收集'!DF16 -> 365
A16: ='总表-数据收集'!B6 -> 花都建设北零跑 | I16: 6 | K16: 从化零跑 | L16: ='总表-数据收集'!AI17 -> 539 | M16: ='总表-数据收集'!BH17 -> 525 | N16: ='总表-数据收集'!CG17 -> 331 | O16: ='总表-数据收集'!DF17 -> 719
A17: KPI | B17: 本周 | C17: 月累 | D17: 目标 | E17: 达成率 | F17: 进度差异 | G17: 离目标差异 | H17: 周趋势 | K17: 清远奇晟 | L17: ='总表-数据收集'!AI18 -> 260 | M17: ='总表-数据收集'!BH18 -> 212 | N17: ='总表-数据收集'!CG18 -> 225 | O17: ='总表-数据收集'!DF18 -> 220
A18: 直播场次 | B18: =#REF! -> #REF! | C18: ='总表-数据收集'!F6 -> 563 | D18: =目标数据!F6 -> 80 | E18: =C18/D18 -> 7.0375 | F18: =C18-D18*E3 -> 501.06452 | G18: =C18-D18 -> 483 | K18: 清远英德 | L18: ='总表-数据收集'!AI19 -> 19 | M18: ='总表-数据收集'!BH19 -> 2 | N18: ='总表-数据收集'!CG19 -> 22 | O18: ='总表-数据收集'!DF19 -> 74
A19: 短视频发布数 | B19: =#REF! -> #REF! | C19: ='总表-数据收集'!G6 -> 847 | D19: =目标数据!G6 -> 90 | E19: =C19/D19 -> 9.4111111 | F19: =C19-D19*E3 -> 777.32258 | G19: =C19-D19 -> 757 | K19: 广花店 | L19: ='总表-数据收集'!AI20 -> 550 | M19: ='总表-数据收集'!BH20 -> 285 | N19: ='总表-数据收集'!CG20 -> 393 | O19: ='总表-数据收集'!DF20 -> 941
A20: 总线索 | B20: =#REF! -> #REF! | C20: ='总表-数据收集'!H6 -> 6156 | D20: =目标数据!M6 -> 1400 | E20: =C20/D20 -> 4.3971429 | F20: =C20-D20*E3 -> 5072.129 | G20: =C20-D20 -> 4756 | K20: 北站店 | L20: ='总表-数据收集'!AI21 -> 188 | M20: ='总表-数据收集'!BH21 -> 84 | N20: ='总表-数据收集'!CG21 -> 282 | O20: ='总表-数据收集'!DF21 -> 398
A21: 总到店 | B21: =#REF! -> #REF! | C21: ='总表-数据收集'!R6 -> 200 | D21: =目标数据!O6 -> 80 | E21: =C21/D21 -> 2.5 | F21: =C21-D21*E3 -> 138.06452 | G21: =C21-D21 -> 120 | K21: 到店
A22: 新媒体订单 | B22: =#REF! -> #REF! | C22: ='总表-数据收集'!U6 -> 59 | D22: =目标数据!P6 -> 20 | E22: =C22/D22 -> 2.95 | F22: =C22-D22*E3 -> 43.516129 | G22: =C22-D22 -> 39 | L22: 4.1-4.5 | M22: 4.6-4.12 | N22: 4.13-4.19 | O22: 4.20-4.30
A23: 新媒体订单占零售订单比例 | B23: ='总表-数据收集'!X6 -> 0.1333 | K23: 花都广本 | L23: ='总表-数据收集'!AS5 -> 77 | M23: ='总表-数据收集'!BR5 -> 22 | N23: ='总表-数据收集'!CQ5 -> 29 | O23: ='总表-数据收集'!DP5 -> 22
A24: 厂家矩阵排名 | B24: ='总表-数据收集'!AC6 -> 0 | K24: 花都建设北零跑 | L24: ='总表-数据收集'!AS6 -> 25 | M24: ='总表-数据收集'!BR6 -> 13 | N24: ='总表-数据收集'!CQ6 -> 26 | O24: ='总表-数据收集'!DP6 -> 51
K25: 白云零跑 | L25: ='总表-数据收集'!AS7 -> 27 | M25: ='总表-数据收集'!BR7 -> 21 | N25: ='总表-数据收集'!CQ7 -> 31 | O25: ='总表-数据收集'!DP7 -> 60
A26: ='总表-数据收集'!B7 -> 白云零跑 | I26: 7 | K26: 花都传祺 | L26: ='总表-数据收集'!AS8 -> 22 | M26: ='总表-数据收集'!BR8 -> 8 | N26: ='总表-数据收集'!CQ8 -> 27 | O26: ='总表-数据收集'!DP8 -> 15
A27: KPI | B27: 本周 | C27: 月累 | D27: 目标 | E27: 达成率 | F27: 进度差异 | G27: 离目标差异 | K27: 清远极氪 | L27: ='总表-数据收集'!AS9 -> 10 | M27: ='总表-数据收集'!BR9 -> 16 | N27: ='总表-数据收集'!CQ9 -> 18 | O27: ='总表-数据收集'!DP9 -> 25
A28: 直播场次 | B28: =#REF! -> #REF! | C28: ='总表-数据收集'!F7 -> 625 | D28: =目标数据!F7 -> 80 | E28: =C28/D28 -> 7.8125 | F28: =C28-D28*E3 -> 563.06452 | G28: =C28-D28 -> 545 | K28: 清远广本 | L28: ='总表-数据收集'!AS10 -> 41 | M28: ='总表-数据收集'!BR10 -> 29 | N28: ='总表-数据收集'!CQ10 -> 50 | O28: ='总表-数据收集'!DP10 -> 33
A29: 短视频发布数 | B29: =#REF! -> #REF! | C29: ='总表-数据收集'!G7 -> 1105 | D29: =目标数据!G7 -> 80 | E29: =C29/D29 -> 13.8125 | F29: =C29-D29*E3 -> 1043.0645 | G29: =C29-D29 -> 1025 | K29: 鑫海广本 | L29: ='总表-数据收集'!AS11 -> 76 | M29: ='总表-数据收集'!BR11 -> 27 | N29: ='总表-数据收集'!CQ11 -> 52 | O29: ='总表-数据收集'!DP11 -> 37
A30: 总线索 | B30: =#REF! -> #REF! | C30: ='总表-数据收集'!H7 -> 6353 | D30: =目标数据!M7 -> 600 | E30: =C30/D30 -> 10.588333 | F30: =C30-D30*E3 -> 5888.4839 | G30: =C30-D30 -> 5753 | K30: 汕头广本 | L30: ='总表-数据收集'!AS12 -> 0 | M30: ='总表-数据收集'!BR12 -> 0 | N30: ='总表-数据收集'!CQ12 -> 41 | O30: ='总表-数据收集'!DP12 -> 25
A31: 总到店 | B31: =#REF! -> #REF! | C31: ='总表-数据收集'!R7 -> 288 | D31: =目标数据!O7 -> 60 | E31: =C31/D31 -> 4.8 | F31: =C31-D31*E3 -> 241.54839 | G31: =C31-D31 -> 228 | H31: 周趋势 | K31: 江门大众 | L31: ='总表-数据收集'!AS13 -> 17 | M31: ='总表-数据收集'!BR13 -> 9 | N31: ='总表-数据收集'!CQ13 -> 22 | O31: ='总表-数据收集'!DP13 -> 10
A32: 新媒体订单 | B32: =#REF! -> #REF! | C32: ='总表-数据收集'!U7 -> 103 | D32: =目标数据!P7 -> 15 | E32: =C32/D32 -> 6.8666667 | F32: =C32-D32*E3 -> 91.387097 | G32: =C32-D32 -> 88 | K32: 河源零跑 | L32: ='总表-数据收集'!AS14 -> 99 | M32: ='总表-数据收集'!BR14 -> 67 | N32: ='总表-数据收集'!CQ14 -> 91 | O32: ='总表-数据收集'!DP14 -> 127
A33: 新媒体订单占零售订单比例 | B33: ='总表-数据收集'!X7 -> 0.25 | K33: 汕头零跑 | L33: ='总表-数据收集'!AS15 -> 54 | M33: ='总表-数据收集'!BR15 -> 47 | N33: ='总表-数据收集'!CQ15 -> 92 | O33: ='总表-数据收集'!DP15 -> 120
A34: 厂家矩阵排名 | B34: ='总表-数据收集'!AC7 -> 263 | K34: 清远港鸿 | L34: ='总表-数据收集'!AS16 -> 54 | M34: ='总表-数据收集'!BR16 -> 11 | N34: ='总表-数据收集'!CQ16 -> 39 | O34: ='总表-数据收集'!DP16 -> 42
K35: 从化零跑 | L35: ='总表-数据收集'!AS17 -> 1 | M35: ='总表-数据收集'!BR17 -> 4 | N35: ='总表-数据收集'!CQ17 -> 11 | O35: ='总表-数据收集'!DP17 -> 25
K36: 清远奇晟 | L36: ='总表-数据收集'!AS18 -> 22 | M36: ='总表-数据收集'!BR18 -> 6 | N36: ='总表-数据收集'!CQ18 -> 11 | O36: ='总表-数据收集'!DP18 -> 29
A37: ='总表-数据收集'!B8 -> 花都传祺 | I37: 8 | K37: 清远英德 | L37: ='总表-数据收集'!AS19 -> 7 | M37: ='总表-数据收集'!BR19 -> 1 | N37: ='总表-数据收集'!CQ19 -> 3 | O37: ='总表-数据收集'!DP19 -> 23
A38: KPI | B38: 本周 | C38: 月累 | D38: 目标 | E38: 达成率 | F38: 进度差异 | G38: 离目标差异 | K38: 广花店 | L38: ='总表-数据收集'!AS20 -> 0 | M38: ='总表-数据收集'!BR20 -> 3 | N38: ='总表-数据收集'!CQ20 -> 8 | O38: ='总表-数据收集'!DP20 -> 28
A39: 直播场次 | B39: =#REF! -> #REF! | C39: ='总表-数据收集'!F8 -> 923 | D39: =目标数据!F8 -> 70 | E39: =C39/D39 -> 13.185714 | F39: =C39-D39*E3 -> 868.80645 | G39: =C39-D39 -> 853 | K39: 北站店 | L39: ='总表-数据收集'!AS21 -> 2 | M39: ='总表-数据收集'!BR21 -> 6 | N39: ='总表-数据收集'!CQ21 -> 21 | O39: ='总表-数据收集'!DP21 -> 28
A40: 短视频发布数 | B40: =#REF! -> #REF! | C40: ='总表-数据收集'!G8 -> 962 | D40: =目标数据!G8 -> 70 | E40: =C40/D40 -> 13.742857 | F40: =C40-D40*E3 -> 907.80645 | G40: =C40-D40 -> 892 | K40: 订单 | L40: 4.1-4.5 | M40: 4.6-4.12 | N40: 4.13-4.19 | O40: 4.20-4.30
...

Sheet 总表-数据收集
A1: 骏延集团2026年1-7月新媒体数据
A2: 序号 | B2: 门店名称 | C2: 1月-7月12日 | AD2: 统计周期：1月1日-31日（合计31天） | BC2: 统计周期：2月1日-28日（合计28天） | CB2: 统计周期3月1日-31日（合计31天） | DA2: 统计周期：4月1日-30日（合计30天） | DZ2: 统计周期：5月1日-31日（合计31天） | EY2: 6月1日-30日（累计30天） | FZ2: 7月1日-12日（累计12天）
C3: 投流 | F3: 直播 场次 | G3: 短视频 发布数量 | H3: 线索 | P3: 到店 | S3: 全月总订单（7月） | T3: 垂媒订单（7月） | U3: 订单(新媒体） | AC3: 截止目前厂家 矩阵 排名 | AD3: 投流 | AG3: 直播 场次 | AH3: 短视频 发布数量 | AI3: 线索 | AQ3: 到店 | AT3: 订单(新媒体） | BB3: 厂家 矩阵 排名 | BC3: 投流 | BF3: 直播 场次 | BG3: 短视频 发布数量 | BH3: 线索 | BP3: 到店 | BS3: 订单(新媒体） | CA3: 厂家 矩阵 排名 | CB3: 投流 | CE3: 直播 场次 | CF3: 短视频 发布数量 | CG3: 线索 | CO3: 到店 | CR3: 订单(新媒体） | CZ3: 厂家 矩阵 排名 | DA3: 投流 | DD3: 直播 场次 | DE3: 短视频 发布数量 | DF3: 线索 | DN3: 到店 | DQ3: 订单(新媒体） | DY3: 厂家 矩阵 排名 | DZ3: 投流 | EC3: 直播 场次 | ED3: 短视频 发布数量 | EE3: 线索 | EM3: 到店 | EP3: 订单(新媒体） | EX3: 厂家 矩阵 排名 | EY3: 投流 | FB3: 直播 场次 | FC3: 短视频 发布数量 | FD3: 线索 | FL3: 到店 | FO3: 全月总订单 | FP3: 垂媒订单 | FQ3: 订单(新媒体） | FY3: 本月截止目前厂家 矩阵 排名 | FZ3: 投流 | GC3: 直播 场次 | GD3: 短视频 发布数量 | GE3: 线索 | GM3: 到店 | GP3: 全月总订单 | GQ3: 垂媒订单 | GR3: 订单(新媒体） | GZ3: 本月截止目前厂家 矩阵 排名
C4: 直播 投流 | D4: 短视频投流 | E4: 总投流 | H4: 总线索 | I4: 直播 线索 | J4: 短视频线索 | K4: 厂家下发线索 | L4: 本地 线索 | M4: 自然流线索数 | N4: 付费流线索数 | O4: 付费流线索成本(元/条） | P4: 直播 到店 | Q4: 短视频到店 | R4: 总到店 | U4: 新媒体总订单 | V4: 直播 订单 | W4: 短视频订单 | X4: 当月新媒体订单占零售订单比例 | Y4: 自然流线索 成交数 | Z4: 自然流线索 成交率 | AA4: 付费流线索 成交数 | AB4: 付费流线索 成交率 | AD4: 直播 投流 | AE4: 短视频投流 | AF4: 总投流 | AI4: 总线索 | AJ4: 直播 线索 | AK4: 短视频线索 | AL4: 厂家下发线索 | AM4: 本地 线索 | AN4: 自然流线索数 | AO4: 付费流线索数 | AP4: 付费流 线索成本 | AQ4: 直播 到店 | AR4: 短视频到店 | AS4: 总到店 | AT4: 新媒体总订单 | AU4: 直播 订单 | AV4: 短视频订单 | AW4: 新媒体订单占零售订单比例 | AX4: 自然流线索 成交数 | AY4: 自然流线索 成交率 | AZ4: 付费流线索 成交数 | BA4: 付费流线索 成交率 | BC4: 直播 投流 | BD4: 短视频投流 | BE4: 总投流 | BH4: 总线索 | BI4: 直播 线索 | BJ4: 短视频线索 | BK4: 厂家下发线索 | BL4: 本地 线索 | BM4: 自然流线索数 | BN4: 付费流线索数 | BO4: 付费流 线索成本 | BP4: 直播 到店 | BQ4: 短视频到店 | BR4: 总到店 | BS4: 新媒体总订单 | BT4: 直播 订单 | BU4: 短视频订单 | BV4: 新媒体订单占零售订单比例 | BW4: 自然流线索 成交数 | BX4: 自然流线索 成交率 | BY4: 付费流线索 成交数 | BZ4: 付费流线索 成交率 | CB4: 直播 投流 | CC4: 短视频投流 | CD4: 总投流 | CG4: 总线索 | CH4: 直播 线索 | CI4: 短视频线索 | CJ4: 厂家下发线索 | CK4: 本地 线索 | CL4: 自然流线索数 | CM4: 付费流线索数 | CN4: 付费流 线索成本 | CO4: 直播 到店 | CP4: 短视频到店 | CQ4: 总到店 | CR4: 新媒体总订单 | CS4: 直播 订单 | CT4: 短视频订单 | CU4: 新媒体订单占零售订单比例 | CV4: 自然流线索 成交数 | CW4: 自然流线索 成交率 | CX4: 付费流线索 成交数 | CY4: 付费流线索 成交率 | DA4: 直播 投流 | DB4: 短视频投流 | DC4: 总投流 | DF4: 总线索 | DG4: 直播 线索 | DH4: 短视频线索 | DI4: 厂家下发线索 | DJ4: 本地 线索 | DK4: 自然流线索数 | DL4: 付费流线索数 | DM4: 付费流 线索成本 | DN4: 直播 到店 | DO4: 短视频到店 | DP4: 总到店 | DQ4: 新媒体总订单 | DR4: 直播 订单 | DS4: 短视频订单 | DT4: 新媒体订单占零售订单比例 | DU4: 自然流线索 成交数 | DV4: 自然流线索 成交率 | DW4: 付费流线索 成交数 | DX4: 付费流线索 成交率 | DZ4: 直播 投流 | EA4: 短视频投流 | EB4: 总投流 | EE4: 总线索 | EF4: 直播 线索 | EG4: 短视频线索 | EH4: 厂家下发线索 | EI4: 本地 线索 | EJ4: 自然流线索数 | EK4: 付费流线索数 | EL4: 付费流 线索成本 | EM4: 直播 到店 | EN4: 短视频到店 | EO4: 总到店 | EP4: 新媒体总订单 | EQ4: 直播 订单 | ER4: 短视频订单 | ES4: 新媒体订单占零售订单比例 | ET4: 自然流线索 成交数 | EU4: 自然流线索 成交率 | EV4: 付费流线索 成交数 | EW4: 付费流线索 成交率 | EY4: 直播 投流 | EZ4: 短视频投流 | FA4: 总投流 | FD4: 总线索 | FE4: 直播 线索 | FF4: 短视频线索 | FG4: 厂家下发线索 | FH4: 本地 线索 | FI4: 自然流线索数 | FJ4: 付费流线索数 | FK4: 付费流线索成本(元/条） | FL4: 直播 到店 | FM4: 短视频到店 | FN4: 总到店 | FQ4: 新媒体总订单 | FR4: 直播 订单 | FS4: 短视频订单 | FT4: 当月新媒体订单占零售订单比例 | FU4: 自然流线索 成交数 | FV4: 自然流线索 成交率 | FW4: 付费流线索 成交数 | FX4: 付费流线索 成交率 | FZ4: 直播 投流 | GA4: 短视频投流 | GB4: 总投流 | GE4: 总线索 | GF4: 直播 线索 | GG4: 短视频线索 | GH4: 厂家下发线索 | GI4: 本地 线索 | GJ4: 自然流线索数 | GK4: 付费流线索数 | GL4: 付费流线索成本(元/条） | GM4: 直播 到店 | GN4: 短视频到店 | GO4: 总到店 | GR4: 新媒体总订单 | GS4: 直播 订单 | GT4: 短视频订单 | GU4: 当月新媒体订单占零售订单比例 | GV4: 自然流线索 成交数 | GW4: 自然流线索 成交率 | GX4: 付费流线索 成交数 | GY4: 付费流线索 成交率
A5: 1 | B5: 花都广本 | C5: =AD5+BC5+CB5+DA5+DZ5+EY5+FZ5 -> 248803.49 | D5: =AE5+BD5+CC5+DB5+EA5+EZ5+GA5 -> 66930.53 | E5: =AF5+BE5+CD5+DC5+EB5+FA5+GB5 -> 315734.02 | F5: =AG5+BF5+CE5+DD5+EC5+FB5+GC5 -> 853 | G5: =AH5+BG5+CF5+DE5+ED5+FC5+GD5 -> 1213 | H5: =AI5+BH5+CG5+DF5+EE5+FD5+GE5 -> 8849 | I5: =AJ5+BI5+CH5+DG5+EF5+FE5+GF5 -> 7118 | J5: =AK5+BJ5+CI5+DH5+EG5+FF5+GG5 -> 703 | ... N5: =AO5+BN5+CM5+DL5+EK5+FJ5+GK5 -> 7580 | O5: =E5/N5 -> 41.653565 | P5: =AQ5+BP5+CO5+DN5+EM5+FL5+GM5 -> 199 | Q5: =AR5+BQ5+CP5+DO5+EN5+FM5+GN5 -> 10 | R5: =AS5+BR5+CQ5+DP5+EO5+FN5+GO5 -> 209 | S5: 26 | T5: 1 | U5: =AT5+BS5+CR5+DQ5+EP5+FQ5+GR5 -> 83 | V5: =AU5+BT5+CS5+DR5+EQ5+FR5+GS5 -> 79 | W5: =AV5+BU5+CT5+DS5+ER5+FS5+GT5 -> 4 | X5: 0.038 | Y5: =AX5+BW5+CV5+DU5+ET5+FU5+GV5 -> 0 | Z5: =AY5+BX5+CW5+DV5+EU5+FV5+GW5 -> 0 | AA5: =AZ5+BY5+CX5+DW5+EV5+FW5+GX5 -> 83 | AB5: =AA5/N5 -> 0.010949868 | AC5: 77 | AD5: 93470.35 | AE5: 18907.78 | AF5: 112378.13 | AG5: 203 | AH5: 295 | AI5: 3099 | AJ5: 2512 | AK5: 238 | AL5: 349 | AM5: 2392 | AN5: 65 | AO5: 2708 | AP5: 41.498571 | AQ5: 67 | AR5: 10 | AS5: 77 | AT5: 36 | AU5: 33 | AV5: 3 | AW5: 0.31 | AX5: 0 | AY5: 0 | AZ5: 36 | BA5: 0.01070901 | BB5: 3 | BC5: 63223.11 | BD5: 13029.01 | BE5: 76252.12 | BF5: 148 | BG5: 367 | BH5: 1529 | BI5: 1373 | BJ5: 109 | BK5: 47 | BL5: 1443 | BM5: 18 | BN5: 1842 | BO5: 41.396374 | BP5: 22 | BQ5: 0 | BR5: 22 | BS5: 4 | BT5: 4 | BU5: 0 | BV5: 0.1 | BW5: 0 | BX5: 0 | BY5: 4 | BZ5: 0.0021715527 | CA5: 5 | CB5: 30312.47 | CC5: 11985.57 | CD5: 42298.04 | CE5: 167 | CF5: 202 | CG5: 1277 | CH5: 1009 | CI5: 123 | CJ5: 145 | CK5: 889 | CL5: 139 | CM5: 991 | CN5: 42.68218 | CO5: 29 | CP5: 0 | CQ5: 29 | CR5: 9 | CS5: 9 | CT5: 0 | CU5: 0.158 | CV5: 0 | CW5: 0 | CX5: 9 | CY5: 0.0090817356 | CZ5: 79 | DA5: 19166.62 | DB5: 0 | DC5: 19166.62 | DD5: 102 | DE5: 98 | DF5: 731 | DG5: 530 | DH5: 6 | DI5: 195 | DJ5: 455 | DK5: 0 | DL5: 474 | DM5: 40.435907 | DN5: 22 | DO5: 0 | DP5: 22 | DQ5: 7 | DR5: 7 | DS5: 0 | DT5: 0.008 | DU5: 0 | DV5: 0 | DW5: 7 | DX5: 0.014767932 | DY5: 103 | DZ5: 14141.01 | EA5: 10629.61 | EB5: 24770.62 | EC5: 110 | ED5: 87 | EE5: 1126 | EF5: 849 | EG5: 130 | EH5: 147 | EI5: 762 | EJ5: 14 | EK5: 739 | EL5: 33.519107 | EM5: 22 | EN5: 0 | EO5: 22 | EP5: 10 | EQ5: 10 | ER5: 0 | ES5: 0.12 | ET5: 0 | EU5: 0 | EV5: 10 | EW5: 0.0135318 | EX5: 41 | EY5: 19526.4 | EZ5: 7878.56 | FA5: 27404.96 | FB5: 88 | FC5: 126 | FD5: 733 | FE5: 600 | FF5: 38 | FG5: 95 | FH5: 501 | FI5: 9 | FJ5: 570 | FK5: 48.078877 | FL5: 35 | FM5: 0 | FN5: 35 | FO5: 101 | FP5: 33 | FQ5: 16 | FR5: 15 | FS5: 1 | FT5: 0.158 | FU5: 0 | FV5: 0 | FW5: 16 | FX5: 0.028070175 | FY5: 8 | FZ5: 8963.53 | GA5: 4500 | GB5: 13463.53 | GC5: 35 | GD5: 38 | GE5: 354 | GF5: 245 | GG5: 59 | GH5: 50 | GI5: 237 | GJ5: 37 | GK5: 256 | GL5: 52.591914 | GM5: 2 | GN5: 0 | GO5: 2 | GP5: 26 | GQ5: 1 | GR5: 1 | GS5: 1 | GT5: 0 | GU5: 0.038 | GV5: 0 | GW5: 0 | GX5: 1 | GY5: 0.00390625 | GZ5: 77
A6: 2 | B6: 花都建设北零跑 | C6: =AD6+BC6+CB6+DA6+DZ6+EY6+FZ6 -> 441404.44 | D6: =AE6+BD6+CC6+DB6+EA6+EZ6+GA6 -> 6925.5 | E6: =AF6+BE6+CD6+DC6+EB6+FA6+GB6 -> 448329.94 | F6: =AG6+BF6+CE6+DD6+EC6+FB6+GC6 -> 563 | G6: =AH6+BG6+CF6+DE6+ED6+FC6+GD6 -> 847 | H6: =AI6+BH6+CG6+DF6+EE6+FD6+GE6 -> 6156 | I6: =AJ6+BI6+CH6+DG6+EF6+FE6+GF6 -> 5775 | J6: =AK6+BJ6+CI6+DH6+EG6+FF6+GG6 -> 160 | ... N6: =AO6+BN6+CM6+DL6+EK6+FJ6+GK6 -> 6618 | O6: =E6/N6 -> 67.744022 | P6: =AQ6+BP6+CO6+DN6+EM6+FL6+GM6 -> 196 | Q6: =AR6+BQ6+CP6+DO6+EN6+FM6+GN6 -> 4 | R6: =AS6+BR6+CQ6+DP6+EO6+FN6+GO6 -> 200 | S6: 30 | T6: 4 | U6: =AT6+BS6+CR6+DQ6+EP6+FQ6+GR6 -> 59 | V6: =AU6+BT6+CS6+DR6+EQ6+FR6+GS6 -> 59 | W6: =AV6+BU6+CT6+DS6+ER6+FS6+GT6 -> 0 | X6: 0.1333 | Y6: =AX6+BW6+CV6+DU6+ET6+FU6+GV6 -> 0 | Z6: =AY6+BX6+CW6+DV6+EU6+FV6+GW6 -> 0 | AA6: =AZ6+BY6+CX6+DW6+EV6+FW6+GX6 -> 59 | AB6: =AA6/N6 -> 0.0089150801 | AD6: 62531.25 | AE6: 0 | AF6: 62531.25 | AG6: 87 | AH6: 103 | AI6: 869 | AJ6: 812 | AK6: 12 | AL6: 45 | AM6: 759 | AN6: 25 | AO6: 838 | AP6: 74.61963 | AQ6: 25 | AR6: 0 | AS6: 25 | AT6: 6 | AU6: 6 | AV6: 0 | AW6: 0.12 | AX6: 0 | AY6: 0 | AZ6: 6 | BA6: 0.0071599045 | BB6: 288 | BC6: 26762.36 | BD6: 0 | BE6: 26762.36 | BF6: 88 | BG6: 119 | BH6: 495 | BI6: 456 | BJ6: 7 | BK6: 32 | BL6: 465 | BM6: 9 | BN6: 451 | BO6: 59.340044 | BP6: 13 | BQ6: 0 | BR6: 13 | BS6: 3 | BT6: 3 | BU6: 0 | BV6: 0.23 | BW6: 0 | BX6: 0 | BY6: 3 | BZ6: 0.0066518847 | CA6: 183 | CB6: 69665.23 | CC6: 3925.5 | CD6: 73590.73 | CE6: 79 | CF6: 131 | CG6: 1446 | CH6: 1309 | CI6: 49 | CJ6: 88 | CK6: 687 | CL6: 25 | CM6: 1341 | CN6: 54.877502 | CO6: 24 | CP6: 2 | CQ6: 26 | CR6: 9 | CS6: 9 | CT6: 0 | CU6: 0.13 | CV6: 0 | CW6: 0 | CX6: 9 | CY6: 0.0067114094 | CZ6: 2 | DA6: 94677.84 | DB6: 0 | DC6: 94677.84 | DD6: 93 | DE6: 163 | DF6: 1054 | DG6: 1045 | DH6: 5 | DI6: 40 | DJ6: 1834 | DK6: 38 | DL6: 1751 | DM6: 54.070725 | DN6: 51 | DO6: 0 | DP6: 51 | DQ6: 12 | DR6: 12 | DS6: 0 | DT6: 0.1043 | DU6: 0 | DV6: 0 | DW6: 12 | DX6: 0.0068532267 | DY6: 269 | DZ6: 120493.48 | EA6: 3000 | EB6: 123493.48 | EC6: 90 | ED6: 129 | EE6: 1412 | EF6: 1283 | EG6: 87 | EH6: 42 | EI6: 1414 | EJ6: 13 | EK6: 1367 | EL6: 90.339049 | EM6: 42 | EN6: 2 | EO6: 44 | EP6: 18 | EQ6: 18 | ER6: 0 | ES6: 0.11 | ET6: 0 | EU6: 0 | EV6: 18 | EW6: 0.01316752 | EX6: 15 | EY6: 44628.54 | EZ6: 0 | FA6: 44628.54 | FB6: 92 | FC6: 166 | FD6: 620 | FE6: 620 | FF6: 0 | FG6: 0 | FH6: 620 | FI6: 0 | FJ6: 620 | FK6: 71.981516 | FL6: 32 | FM6: 0 | FN6: 32 | FO6: 86 | FP6: 26 | FQ6: 7 | FR6: 7 | FS6: 0 | FT6: 0.081 | FU6: 0 | FV6: 0 | FW6: 7 | FX6: 0.011290323 | FY6: 236 | FZ6: 22645.74 | GA6: 0 | GB6: 22645.74 | GC6: 34 | GD6: 36 | GE6: 260 | GF6: 250 | GG6: 0 | GH6: 10 | GI6: 260 | GJ6: 0 | GK6: 250 | GL6: 90.58296 | GM6: 9 | GN6: 0 | GO6: 9 | GP6: 30 | GQ6: 4 | GR6: 4 | GS6: 4 | GT6: 0 | GU6: 0.1333 | GV6: 0 | GW6: 0 | GX6: 4 | GY6: 0.016
A7: 3 | B7: 白云零跑 | C7: =AD7+BC7+CB7+DA7+DZ7+EY7+FZ7 -> 346441.97 | D7: =AE7+BD7+CC7+DB7+EA7+EZ7+GA7 -> 109443.11 | E7: =AF7+BE7+CD7+DC7+EB7+FA7+GB7 -> 455885.08 | F7: =AG7+BF7+CE7+DD7+EC7+FB7+GC7 -> 625 | G7: =AH7+BG7+CF7+DE7+ED7+FC7+GD7 -> 1105 | H7: =AI7+BH7+CG7+DF7+EE7+FD7+GE7 -> 6353 | I7: =AJ7+BI7+CH7+DG7+EF7+FE7+GF7 -> 4677 | J7: =AK7+BJ7+CI7+DH7+EG7+FF7+GG7 -> 1365 | ... N7: =AO7+BN7+CM7+DL7+EK7+FJ7+GK7 -> 6121 | O7: =E7/N7 -> 74.478856 | P7: =AQ7+BP7+CO7+DN7+EM7+FL7+GM7 -> 284 | Q7: =AR7+BQ7+CP7+DO7+EN7+FM7+GN7 -> 4 | R7: =AS7+BR7+CQ7+DP7+EO7+FN7+GO7 -> 288 | S7: 40 | T7: 11 | U7: =AT7+BS7+CR7+DQ7+EP7+FQ7+GR7 -> 103 | V7: =AU7+BT7+CS7+DR7+EQ7+FR7+GS7 -> 102 | W7: =AV7+BU7+CT7+DS7+ER7+FS7+GT7 -> 1 | X7: 0.25 | Y7: =AX7+BW7+CV7+DU7+ET7+FU7+GV7 -> 0 | Z7: =AY7+BX7+CW7+DV7+EU7+FV7+GW7 -> 0 | AA7: =AZ7+BY7+CX7+DW7+EV7+FW7+GX7 -> 103 | AB7: =AA7/N7 -> 0.016827316 | AC7: 263 | AD7: 68020.21 | AE7: 30054.05 | AF7: 98074.26 | AG7: 94 | AH7: 172 | AI7: 1160 | AJ7: 794 | AK7: 223 | AL7: 143 | AM7: 1014 | AN7: 18 | AO7: 1021 | AP7: 96.057062 | AQ7: 25 | AR7: 2 | AS7: 27 | AT7: 6 | AU7: 6 | AV7: 0 | AW7: 0.06 | AX7: 0 | AY7: 0 | AZ7: 6 | BA7: 0.0058765916 | BB7: 315 | BC7: 49912.45 | BD7: 18274.88 | BE7: 68187.33 | BF7: 97 | BG7: 136 | BH7: 681 | BI7: 562 | BJ7: 84 | BK7: 35 | BL7: 594 | BM7: 3 | BN7: 608 | BO7: 112.15021 | BP7: 21 | BQ7: 0 | BR7: 21 | BS7: 13 | BT7: 13 | BU7: 0 | BV7: 0.6 | BW7: 0 | BX7: 0 | BY7: 13 | BZ7: 0.021381579 | CA7: 207 | CB7: 45981.03 | CC7: 27252.22 | CD7: 73233.25 | CE7: 77 | CF7: 218 | CG7: 902 | CH7: 681 | CI7: 189 | CJ7: 32 | CK7: 988 | CL7: 14 | CM7: 979 | CN7: 74.804137 | CO7: 31 | CP7: 0 | CQ7: 31 | CR7: 17 | CS7: 17 | CT7: 0 | CU7: 0.346 | CV7: 0 | CW7: 0 | CX7: 17 | CY7: 0.017364658 | CZ7: 186 | DA7: 54056.11 | DB7: 13435.97 | DC7: 67492.08 | DD7: 97 | DE7: 197 | DF7: 1112 | DG7: 955 | DH7: 137 | DI7: 20 | DJ7: 974 | DK7: 6 | DL7: 1087 | DM7: 62.09023 | DN7: 60 | DO7: 0 | DP7: 60 | DQ7: 16 | DR7: 16 | DS7: 0 | DT7: 0.1 | DU7: 0 | DV7: 0 | DW7: 16 | DX7: 0.014719411 | DY7: 147 | DZ7: 46847 | EA7: 1143 | EB7: 47990 | EC7: 115 | ED7: 165 | EE7: 1084 | EF7: 673 | EG7: 353 | EH7: 58 | EI7: 896 | EJ7: 30 | EK7: 1026 | EL7: 46.773879 | EM7: 61 | EN7: 0 | EO7: 61 | EP7: 20 | EQ7: 20 | ER7: 0 | ES7: 0.233 | ET7: 0 | EU7: 0 | EV7: 20 | EW7: 0.019493177 | EX7: 230 | EY7: 55103.34 | EZ7: 15228.73 | FA7: 70332.07 | FB7: 107 | FC7: 167 | FD7: 1014 | FE7: 666 | FF7: 332 | FG7: 16 | FH7: 1014 | FI7: 0 | FJ7: 1014 | FK7: 69.361016 | FL7: 65 | FM7: 1 | FN7: 66 | FO7: 91 | FP7: 27 | FQ7: 20 | FR7: 19 | FS7: 1 | FT7: 0.219 | FU7: 0 | FV7: 0 | FW7: 20 | FX7: 0.019723866 | FY7: 185 | FZ7: 26521.83 | GA7: 4054.26 | GB7: 30576.09 | GC7: 38 | GD7: 50 | GE7: 400 | GF7: 346 | GG7: 47 | GH7: 7 | GI7: 383 | GJ7: 0 | GK7: 386 | GL7: 79.212668 | GM7: 21 | GN7: 1 | GO7: 22 | GP7: 40 | GQ7: 11 | GR7: 11 | GS7: 11 | GT7: 0 | GU7: 0.25 | GV7: 0 | GW7: 0 | GX7: 11 | GY7: 0.028497409 | GZ7: 263
A8: 4 | B8: 花都传祺 | C8: =AD8+BC8+CB8+DA8+DZ8+EY8+FZ8 -> 224870.74 | D8: =AE8+BD8+CC8+DB8+EA8+EZ8+GA8 -> 77650.68 | E8: =AF8+BE8+CD8+DC8+EB8+FA8+GB8 -> 302521.42 | F8: =AG8+BF8+CE8+DD8+EC8+FB8+GC8 -> 923 | G8: =AH8+BG8+CF8+DE8+ED8+FC8+GD8 -> 962 | H8: =AI8+BH8+CG8+DF8+EE8+FD8+GE8 -> 4306 | I8: =AJ8+BI8+CH8+DG8+EF8+FE8+GF8 -> 2579 | J8: =AK8+BJ8+CI8+DH8+EG8+FF8+GG8 -> 1317 | ... N8: =AO8+BN8+CM8+DL8+EK8+FJ8+GK8 -> 3370 | O8: =E8/N8 -> 89.768967 | P8: =AQ8+BP8+CO8+DN8+EM8+FL8+GM8 -> 124 | Q8: =AR8+BQ8+CP8+DO8+EN8+FM8+GN8 -> 31 | R8: =AS8+BR8+CQ8+DP8+EO8+FN8+GO8 -> 155 | S8: 9 | T8: 1 | U8: =AT8+BS8+CR8+DQ8+EP8+FQ8+GR8 -> 40 | V8: =AU8+BT8+CS8+DR8+EQ8+FR8+GS8 -> 31 | W8: =AV8+BU8+CT8+DS8+ER8+FS8+GT8 -> 9 | X8: 0.44 | Y8: =AX8+BW8+CV8+DU8+ET8+FU8+GV8 -> 0 | Z8: =AY8+BX8+CW8+DV8+EU8+FV8+GW8 -> 0 | AA8: =AZ8+BY8+CX8+DW8+EV8+FW8+GX8 -> 40 | AB8: =AA8/N8 -> 0.011869436 | AC8: 133 | AD8: 33306 | AE8: 18161 | AF8: 51467 | AG8: 141 | AH8: 137 | AI8: 579 | AJ8: 303 | AK8: 234 | AL8: 42 | AM8: 468 | AN8: 47 | AO8: 490 | AP8: 105.03469 | AQ8: 14 | AR8: 8 | AS8: 22 | AT8: 7 | AU8: 3 | AV8: 4 | AW8: 0.12 | AX8: 0 | AY8: 0 | AZ8: 7 | BA8: 0.014285714 | BB8: 167 | BC8: 13103.99 | BD8: 8591.8 | BE8: 21695.79 | BF8: 123 | BG8: 113 | BH8: 302 | BI8: 128 | BJ8: 135 | BK8: 39 | BL8: 254 | BM8: 162 | BN8: 101 | BO8: 214.8098 | BP8: 7 | BQ8: 1 | BR8: 8 | BS8: 3 | BT8: 2 | BU8: 1 | BV8: 0.17 | BW8: 0 | BX8: 0 | BY8: 3 | BZ8: 0.02970297 | CB8: 42719.18 | CC8: 26942.88 | CD8: 69662.06 | CE8: 108 | CF8: 105 | CG8: 870 | CH8: 424 | CI8: 284 | CJ8: 162 | CK8: 656 | CL8: 40 | CM8: 623 | CN8: 111.81711 | CO8: 22 | CP8: 5 | CQ8: 27 | CR8: 7 | CS8: 6 | CT8: 1 | CU8: 0.18 | CV8: 0 | CW8: 0 | CX8: 7 | CY8: 0.011235955 | DA8: 21202.57 | DB8: 10046 | DC8: 31248.57 | DD8: 135 | DE8: 132 | DF8: 557 | DG8: 256 | DH8: 248 | DI8: 53 | DJ8: 433 | DK8: 38 | DL8: 456 | DM8: 68.527566 | DN8: 12 | DO8: 3 | DP8: 15 | DQ8: 3 | DR8: 3 | DS8: 0 | DT8: 0.1 | DU8: 0 | DV8: 0 | DW8: 3 | DX8: 0.0065789474 | DZ8: 33449 | EA8: 11733 | EB8: 45182 | EC8: 143 | ED8: 151 | EE8: 682 | EF8: 373 | EG8: 257 | EH8: 52 | EI8: 520 | EJ8: 59 | EK8: 561 | EL8: 80.538324 | EM8: 22 | EN8: 8 | EO8: 30 | EP8: 8 | EQ8: 5 | ER8: 3 | ES8: 0.18 | ET8: 0 | EU8: 0 | EV8: 8 | EW8: 0.01426025 | EX8: 107 | EY8: 52473 | EZ8: 1648 | FA8: 54121 | FB8: 181 | FC8: 243 | FD8: 860 | FE8: 703 | FF8: 121 | FG8: 36 | FH8: 698 | FI8: 59 | FJ8: 718 | FK8: 75.377437 | FL8: 31 | FM8: 0 | FN8: 31 | FO8: 45 | FP8: 11 | FQ8: 8 | FR8: 8 | FS8: 0 | FT8: 0.1778 | FU8: 0 | FV8: 0 | FW8: 8 | FX8: 0.011142061 | FY8: 117 | FZ8: 28617 | GA8: 528 | GB8: 29145 | GC8: 92 | GD8: 81 | GE8: 456 | GF8: 392 | GG8: 38 | GH8: 26 | GI8: 335 | GJ8: 14 | GK8: 421 | GL8: 69.228029 | GM8: 16 | GN8: 6 | GO8: 22 | GP8: 9 | GQ8: 1 | GR8: 4 | GS8: 4 | GT8: 0 | GU8: 0.44 | GV8: 0 | GW8: 0 | GX8: 4 | GY8: 0.0095011876 | GZ8: 133
A9: 5 | B9: 清远极氪 | C9: =AD9+BC9+CB9+DA9+DZ9+EY9+FZ9 -> 137540.58 | D9: =AE9+BD9+CC9+DB9+EA9+EZ9+GA9 -> 22631.53 | E9: =AF9+BE9+CD9+DC9+EB9+FA9+GB9 -> 160172.11 | F9: =AG9+BF9+CE9+DD9+EC9+FB9+GC9 -> 520 | G9: =AH9+BG9+CF9+DE9+ED9+FC9+GD9 -> 389 | H9: =AI9+BH9+CG9+DF9+EE9+FD9+GE9 -> 2168 | I9: =AJ9+BI9+CH9+DG9+EF9+FE9+GF9 -> 1845 | J9: =AK9+BJ9+CI9+DH9+EG9+FF9+GG9 -> 268 | ... N9: =AO9+BN9+CM9+DL9+EK9+FJ9+GK9 -> 1901 | O9: =E9/N9 -> 84.256765 | P9: =AQ9+BP9+CO9+DN9+EM9+FL9+GM9 -> 128 | Q9: =AR9+BQ9+CP9+DO9+EN9+FM9+GN9 -> 1 | R9: =AS9+BR9+CQ9+DP9+EO9+FN9+GO9 -> 129 | S9: 5 | T9: 1 | U9: =AT9+BS9+CR9+DQ9+EP9+FQ9+GR9 -> 16 | V9: =AU9+BT9+CS9+DR9+EQ9+FR9+GS9 -> 16 | W9: =AV9+BU9+CT9+DS9+ER9+FS9+GT9 -> 0 | X9: 0.2 | Y9: =AX9+BW9+CV9+DU9+ET9+FU9+GV9 -> 0 | Z9: =AY9+BX9+CW9+DV9+EU9+FV9+GW9 -> 0.533 | AA9: =AZ9+BY9+CX9+DW9+EV9+FW9+GX9 -> 16 | AB9: =AA9/N9 -> 0.0084166228 | AD9: 3841.5 | AE9: 438.73 | AF9: 4280.23 | AG9: 35 | AH9: 35 | AI9: 68 | AJ9: 38 | AK9: 11 | AL9: 19 | AM9: 57 | AN9: 5 | AO9: 29 | AP9: 147.59414 | AQ9: 10 | AR9: 0 | AS9: 10 | AT9: 1 | AU9: 1 | AV9: 0 | AW9: 0 | AX9: 0 | AY9: 0 | AZ9: 1 | BA9: 0.034482759 | BC9: 13841 | BD9: 11356 | BE9: 25197 | BF9: 57 | BG9: 83 | BH9: 369 | BI9: 227 | BJ9: 137 | BK9: 5 | BL9: 67 | BM9: 8 | BN9: 353 | BO9: 71.379603 | BP9: 15 | BQ9: 1 | BR9: 16 | BS9: 0 | BT9: 0 | BU9: 0 | BV9: 0 | BW9: 0 | BX9: 0 | BY9: 0 | BZ9: 0 | CB9: 25871 | CC9: 3777 | CD9: 29648 | CE9: 99 | CF9: 66 | CG9: 345 | CH9: 314 | CI9: 19 | CJ9: 0 | CK9: 173 | CL9: 30 | CM9: 321 | CN9: 92.361371 | CO9: 18 | CP9: 0 | CQ9: 18 | CR9: 2 | CS9: 2 | CT9: 0 | CU9: 0.03 | CV9: 0 | CW9: 0 | CX9: 2 | CY9: 0.0062305296 | DA9: 29189.22 | DB9: 3152 | DC9: 32341.22 | DD9: 96 | DE9: 64 | DF9: 384 | DG9: 336 | DH9: 44 | DI9: 4 | DJ9: 179 | DK9: 13 | DL9: 364 | DM9: 88.849505 | DN9: 25 | DO9: 0 | DP9: 25 | DQ9: 2 | DR9: 2 | DS9: 0 | DT9: 0.067 | DU9: 0 | DV9: 0.533 | DW9: 2 | DX9: 0.0054945055 | DZ9: 28448 | EA9: 1173 | EB9: 29621 | EC9: 96 | ED9: 60 | EE9: 408 | EF9: 387 | EG9: 21 | EH9: 0 | EI9: 276 | EJ9: 26 | EK9: 390 | EL9: 75.951282 | EM9: 33 | EN9: 0 | EO9: 33 | EP9: 6 | EQ9: 6 | ER9: 0 | ES9: 0.136 | ET9: 0 | EU9: 0 | EV9: 6 | EW9: 0.015384615 | EY9: 25412.86 | EZ9: 2134.8 | FA9: 27547.66 | FB9: 96 | FC9: 60 | FD9: 418 | FE9: 375 | FF9: 28 | FG9: 15 | FH9: 300 | FI9: 77 | FJ9: 316 | FK9: 87.176139 | FL9: 20 | FM9: 0 | FN9: 20 | FO9: 30 | FP9: 4 | FQ9: 4 | FR9: 4 | FS9: 0 | FT9: 0.115 | FU9: 0 | FV9: 0 | FW9: 4 | FX9: 0.012658228 | FZ9: 10937 | GA9: 600 | GB9: 11537 | GC9: 41 | GD9: 21 | GE9: 176 | GF9: 168 | GG9: 8 | GH9: 0 | GI9: 100 | GJ9: 50 | GK9: 128 | GL9: 90.132812 | GM9: 7 | GN9: 0 | GO9: 7 | GP9: 5 | GQ9: 1 | GR9: 1 | GS9: 1 | GT9: 0 | GU9: 0.2 | GV9: 0 | GW9: 0 | GX9: 1 | GY9: 0.0078125
A10: 6 | B10: 清远广本 | C10: =AD10+BC10+CB10+DA10+DZ10+EY10+FZ10 -> 52194.65 | D10: =AE10+BD10+CC10+DB10+EA10+EZ10+GA10 -> 0 | E10: =AF10+BE10+CD10+DC10+EB10+FA10+GB10 -> 52194.65 | F10: =AG10+BF10+CE10+DD10+EC10+FB10+GC10 -> 448 | G10: =AH10+BG10+CF10+DE10+ED10+FC10+GD10 -> 452 | H10: =AI10+BH10+CG10+DF10+EE10+FD10+GE10 -> 4068 | I10: =AJ10+BI10+CH10+DG10+EF10+FE10+GF10 -> 1883 | J10: =AK10+BJ10+CI10+DH10+EG10+FF10+GG10 -> 529 | ... N10: =AO10+BN10+CM10+DL10+EK10+FJ10+GK10 -> 1014 | O10: =E10/N10 -> 51.474014 | P10: =AQ10+BP10+CO10+DN10+EM10+FL10+GM10 -> 218 | Q10: =AR10+BQ10+CP10+DO10+EN10+FM10+GN10 -> 31 | R10: =AS10+BR10+CQ10+DP10+EO10+FN10+GO10 -> 249 | S10: 12 | T10: 0 | U10: =AT10+BS10+CR10+DQ10+EP10+FQ10+GR10 -> 59 | V10: =AU10+BT10+CS10+DR10+EQ10+FR10+GS10 -> 52 | W10: =AV10+BU10+CT10+DS10+ER10+FS10+GT10 -> 7 | X10: 0 | Y10: =AX10+BW10+CV10+DU10+ET10+FU10+GV10 -> 18 | Z10: =AY10+BX10+CW10+DV10+EU10+FV10+GW10 -> 0.92209466 | AA10: =AZ10+BY10+CX10+DW10+EV10+FW10+GX10 -> 41 | AB10: =AA10/N10 -> 0.040433925 | AC10: 99 | AD10: 0 | AE10: 0 | AF10: 0 | AG10: 65 | AH10: 58 | AI10: 683 | AJ10: 170 | AK10: 111 | AL10: 402 | AM10: 66 | AN10: 198 | AO10: 0 | AP10: 0 | AQ10: 36 | AR10: 5 | AS10: 41 | AT10: 11 | AU10: 9 | AV10: 2 | AW10: 0.21 | AX10: 1 | AY10: 0.1026455 | AZ10: 10 | BA10: 0 | BB10: 141 | BC10: 0 | BD10: 0 | BE10: 0 | BF10: 45 | BG10: 58 | BH10: 765 | BI10: 229 | BJ10: 75 | BK10: 461 | BL10: 86 | BM10: 252 | BN10: 0 | BO10: 0 | BP10: 22 | BQ10: 7 | BR10: 29 | BS10: 5 | BT10: 4 | BU10: 1 | BV10: 0.11 | BW10: 5 | BX10: 0.079449153 | BY10: 0 | BZ10: 0 | CA10: 88 | CB10: 15070.65 | CC10: 0 | CD10: 15070.65 | CE10: 96 | CF10: 93 | CG10: 867 | CH10: 348 | CI10: 136 | CJ10: 383 | CK10: 203 | CL10: 122 | CM10: 270 | CN10: 55.817222 | CO10: 44 | CP10: 6 | CQ10: 50 | CR10: 9 | CS10: 8 | CT10: 1 | CU10: 0.2 | CV10: 1 | CW10: 0.024 | CX10: 8 | CY10: 0.02962963 | CZ10: 161 | DA10: 4592 | DB10: 0 | DC10: 4592 | DD10: 74 | DE10: 80 | DF10: 593 | DG10: 307 | DH10: 93 | DI10: 193 | DJ10: 72 | DK10: 150 | DL10: 45 | DM10: 102.04444 | DN10: 28 | DO10: 5 | DP10: 33 | DQ10: 7 | DR10: 7 | DS10: 0 | DT10: 0.17 | DU10: 3 | DV10: 0.236 | DW10: 4 | DX10: 0.088888889 | DY10: 252 | DZ10: 15729 | EA10: 0 | EB10: 15729 | EC10: 82 | ED10: 83 | EE10: 525 | EF10: 363 | EG10: 55 | EH10: 110 | EI10: 215 | EJ10: 97 | EK10: 324 | EL10: 32.931034 | EM10: 38 | EN10: 4 | EO10: 42 | EP10: 10 | EQ10: 8 | ER10: 2 | ES10: 0.227 | ET10: 4 | EU10: 0.263 | EV10: 6 | EW10: 0.01061008 | EX10: 149 | EY10: 11857 | EZ10: 0 | FA10: 11857 | FB10: 68 | FC10: 72 | FD10: 480 | FE10: 343 | FF10: 47 | FG10: 90 | FH10: 143 | FI10: 103 | FJ10: 276 | FK10: 42.960145 | FL10: 41 | FM10: 4 | FN10: 45 | FO10: 61 | FP10: 17 | FQ10: 17 | FR10: 16 | FS10: 1 | FT10: 0.278 | FU10: 4 | FV10: 0.217 | FW10: 13 | FX10: 0.047101449 | FY10: 134 | FZ10: 4946 | GA10: 0 | GB10: 4946 | GC10: 18 | GD10: 8 | GE10: 155 | GF10: 123 | GG10: 12 | GH10: 20 | GI10: 83 | GJ10: 46 | GK10: 99 | GL10: 49.959596 | GM10: 9 | GN10: 0 | GO10: 9 | GP10: 12 | GQ10: 0 | GR10: 0 | GS10: 0 | GT10: 0 | GU10: 0 | GV10: 0 | GW10: 0 | GX10: 0 | GY10: 0 | GZ10: 99
A11: 7 | B11: 鑫海广本 | C11: =AD11+BC11+CB11+DA11+DZ11+EY11+FZ11 -> 71200 | D11: =AE11+BD11+CC11+DB11+EA11+EZ11+GA11 -> 0 | E11: =AF11+BE11+CD11+DC11+EB11+FA11+GB11 -> 71200 | F11: =AG11+BF11+CE11+DD11+EC11+FB11+GC11 -> 400 | G11: =AH11+BG11+CF11+DE11+ED11+FC11+GD11 -> 306 | H11: =AI11+BH11+CG11+DF11+EE11+FD11+GE11 -> 2170 | I11: =AJ11+BI11+CH11+DG11+EF11+FE11+GF11 -> 1528 | J11: =AK11+BJ11+CI11+DH11+EG11+FF11+GG11 -> 192 | ... N11: =AO11+BN11+CM11+DL11+EK11+FJ11+GK11 -> 1682 | O11: =E11/N11 -> 42.330559 | P11: =AQ11+BP11+CO11+DN11+EM11+FL11+GM11 -> 251 | Q11: =AR11+BQ11+CP11+DO11+EN11+FM11+GN11 -> 30 | R11: =AS11+BR11+CQ11+DP11+EO11+FN11+GO11 -> 281 | S11: 5 | T11: 1 | U11: =AT11+BS11+CR11+DQ11+EP11+FQ11+GR11 -> 54 | V11: =AU11+BT11+CS11+DR11+EQ11+FR11+GS11 -> 54 | W11: =AV11+BU11+CT11+DS11+ER11+FS11+GT11 -> 1 | X11: 0.2 | Y11: =AX11+BW11+CV11+DU11+ET11+FU11+GV11 -> 1 | Z11: =AY11+BX11+CW11+DV11+EU11+FV11+GW11 -> 0.045 | AA11: =AZ11+BY11+CX11+DW11+EV11+FW11+GX11 -> 53 | AB11: =AA11/N11 -> 0.031510107 | AC11: 200 | AD11: 15000 | AE11: 0 | AF11: 15000 | AG11: 76 | AH11: 55 | AI11: 502 | AJ11: 372 | AK11: 54 | AL11: 76 | AM11: 275 | AN11: 86 | AO11: 416 | AP11: 36.057692 | AQ11: 65 | AR11: 11 | AS11: 76 | AT11: 15 | AU11: 15 | AV11: 0 | AW11: 0.15 | AX11: 0 | AY11: 0 | AZ11: 15 | BA11: 0.036057692 | BB11: 200 | BC11: 7000 | BD11: 0 | BE11: 7000 | BF11: 50 | BG11: 30 | BH11: 181 | BI11: 110 | BJ11: 28 | BK11: 43 | BL11: 102 | BM11: 45 | BN11: 136 | BO11: 51.470588 | BP11: 24 | BQ11: 3 | BR11: 27 | BS11: 7 | BT11: 7 | BU11: 1 | BV11: 0.15 | BW11: 0 | BX11: 0 | BY11: 7 | BZ11: 0.058823529 | CA11: 230 | CB11: 11500 | CC11: 0 | CD11: 11500 | CE11: 70 | CF11: 60 | CG11: 394 | CH11: 274 | CI11: 35 | CJ11: 85 | CK11: 206 | CL11: 71 | CM11: 313 | CN11: 36.741214 | CO11: 49 | CP11: 3 | CQ11: 52 | CR11: 10 | CS11: 10 | CT11: 0 | CU11: 0.15 | CV11: 0 | CW11: 0 | CX11: 10 | CY11: 0.031948882 | CZ11: 220 | DA11: 9600 | DB11: 0 | DC11: 9600 | DD11: 62 | DE11: 60 | DF11: 316 | DG11: 219 | DH11: 19 | DI11: 78 | DJ11: 170 | DK11: 58 | DL11: 258 | DM11: 37.209302 | DN11: 35 | DO11: 2 | DP11: 37 | DQ11: 5 | DR11: 5 | DS11: 0 | DT11: 0.15 | DU11: 0 | DV11: 0 | DW11: 5 | DX11: 0.019379845 | DY11: 198 | DZ11: 14100 | EA11: 0 | EB11: 14100 | EC11: 68 | ED11: 46 | EE11: 375 | EF11: 257 | EG11: 36 | EH11: 82 | EI11: 207 | EJ11: 97 | EK11: 261 | EL11: 54.022989 | EM11: 41 | EN11: 9 | EO11: 50 | EP11: 10 | EQ11: 10 | ER11: 0 | ES11: 0.15 | ET11: 1 | EU11: 0.045 | EV11: 9 | EW11: 0.034482759 | EX11: 208 | EY11: 11000 | EZ11: 0 | FA11: 11000 | FB11: 61 | FC11: 48 | FD11: 336 | FE11: 247 | FF11: 18 | FG11: 71 | FH11: 186 | FI11: 78 | FJ11: 246 | FK11: 44.715447 | FL11: 33 | FM11: 2 | FN11: 35 | FO11: 15 | FP11: 4 | FQ11: 6 | FR11: 6 | FS11: 0 | FT11: 0.26 | FU11: 0 | FV11: 0 | FW11: 6 | FX11: 0.024390244 | FY11: 200 | FZ11: 3000 | GA11: 0 | GB11: 3000 | GC11: 13 | GD11: 7 | GE11: 66 | GF11: 49 | GG11: 2 | GH11: 15 | GI11: 38 | GJ11: 14 | GK11: 52 | GL11: 57.692308 | GM11: 4 | GN11: 0 | GO11: 4 | GP11: 5 | GQ11: 1 | GR11: 1 | GS11: 1 | GT11: 0 | GU11: 0.2 | GV11: 0 | GW11: 0 | GX11: 1 | GY11: 0.019230769 | GZ11: 200
A12: 8 | B12: 汕头广本 | C12: =AD12+BC12+CB12+DA12+DZ12+EY12+FZ12 -> 32703.45 | D12: =AE12+BD12+CC12+DB12+EA12+EZ12+GA12 -> 31043.26 | E12: =AF12+BE12+CD12+DC12+EB12+FA12+GB12 -> 63746.71 | F12: =AG12+BF12+CE12+DD12+EC12+FB12+GC12 -> 239 | G12: =AH12+BG12+CF12+DE12+ED12+FC12+GD12 -> 302 | H12: =AI12+BH12+CG12+DF12+EE12+FD12+GE12 -> 2377 | I12: =AJ12+BI12+CH12+DG12+EF12+FE12+GF12 -> 740 | J12: =AK12+BJ12+CI12+DH12+EG12+FF12+GG12 -> 1566 | ... N12: =AO12+BN12+CM12+DL12+EK12+FJ12+GK12 -> 1648 | O12: =E12/N12 -> 38.681256 | P12: =AQ12+BP12+CO12+DN12+EM12+FL12+GM12 -> 39 | Q12: =AR12+BQ12+CP12+DO12+EN12+FM12+GN12 -> 101 | R12: =AS12+BR12+CQ12+DP12+EO12+FN12+GO12 -> 140 | S12: 3 | T12: 0 | U12: =AT12+BS12+CR12+DQ12+EP12+FQ12+GR12 -> 47 | V12: =AU12+BT12+CS12+DR12+EQ12+FR12+GS12 -> 12 | W12: =AV12+BU12+CT12+DS12+ER12+FS12+GT12 -> 34 | X12: 0.33 | Y12: =AX12+BW12+CV12+DU12+ET12+FU12+GV12 -> 3 | Z12: =AY12+BX12+CW12+DV12+EU12+FV12+GW12 -> 0.076 | AA12: =AZ12+BY12+CX12+DW12+EV12+FW12+GX12 -> 44 | AB12: =AA12/N12 -> 0.026699029 | CB12: 904.83 | CC12: 5469.44 | CD12: 6374.27 | CE12: 56 | CF12: 91 | CG12: 461 | CH12: 64 | CI12: 391 | CJ12: 7 | CK12: 608 | CL12: 265 | CM12: 188 | CN12: 33.905691 | CO12: 4 | CP12: 37 | CQ12: 41 | CR12: 16 | CS12: 3 | CT12: 13 | CU12: 0.15 | CV12: 2 | CW12: 0.028 | CX12: 14 | CY12: 0.074468085 | CZ12: 189 | DA12: 7632.9 | DB12: 10115.68 | DC12: 17748.58 | DD12: 52 | DE12: 64 | DF12: 497 | DG12: 147 | DH12: 329 | DI12: 21 | DJ12: 548 | DK12: 109 | DL12: 379 | DM12: 46.830026 | DN12: 4 | DO12: 21 | DP12: 25 | DQ12: 9 | DR12: 1 | DS12: 7 | DT12: 0.12 | DU12: 0 | DV12: 0 | DW12: 9 | DX12: 0.023746702 | DY12: 159 | DZ12: 11365.12 | EA12: 8463.25 | EB12: 19828.37 | EC12: 54 | ED12: 50 | EE12: 537 | EF12: 231 | EG12: 304 | EH12: 2 | EI12: 527 | EJ12: 60 | EK12: 495 | EL12: 40.057313 | EM12: 13 | EN12: 13 | EO12: 26 | EP12: 10 | EQ12: 3 | ER12: 7 | ES12: 0.18 | ET12: 0 | EU12: 0 | EV12: 10 | EW12: 0.02020202 | EX12: 152 | EY12: 10611.56 | EZ12: 5279.96 | FA12: 15891.52 | FB12: 57 | FC12: 80 | FD12: 682 | FE12: 247 | FF12: 398 | FG12: 37 | FH12: 627 | FI12: 82 | FJ12: 425 | FK12: 37.391812 | FL12: 15 | FM12: 20 | FN12: 35 | FO12: 54 | FP12: 5 | FQ12: 9 | FR12: 4 | FS12: 5 | FT12: 0.167 | FU12: 1 | FV12: 0.048 | FW12: 8 | FX12: 0.018823529 | FY12: 300 | FZ12: 2189.04 | GA12: 1714.93 | GB12: 3903.97 | GC12: 20 | GD12: 17 | GE12: 200 | GF12: 51 | GG12: 144 | GH12: 5 | GI12: 198 | GJ12: 26 | GK12: 161 | GL12: 24.248261 | GM12: 3 | GN12: 10 | GO12: 13 | GP12: 3 | GQ12: 0 | GR12: 3 | GS12: 1 | GT12: 2 | GU12: 0.33 | GV12: 0 | GW12: 0 | GX12: 3 | GY12: 0.01863354 | GZ12: 203
A13: 9 | B13: 江门大众 | C13: =AD13+BC13+CB13+DA13+DZ13+EY13+FZ13 -> 31485 | D13: =AE13+BD13+CC13+DB13+EA13+EZ13+GA13 -> 106328 | E13: =AF13+BE13+CD13+DC13+EB13+FA13+GB13 -> 145188 | F13: =AG13+BF13+CE13+DD13+EC13+FB13+GC13 -> 159 | G13: =AH13+BG13+CF13+DE13+ED13+FC13+GD13 -> 433 | H13: =AI13+BH13+CG13+DF13+EE13+FD13+GE13 -> 1987 | I13: =AJ13+BI13+CH13+DG13+EF13+FE13+GF13 -> 234 | J13: =AK13+BJ13+CI13+DH13+EG13+FF13+GG13 -> 1282 | ... N13: =AO13+BN13+CM13+DL13+EK13+FJ13+GK13 -> 2387 | O13: =E13/N13 -> 60.824466 | P13: =AQ13+BP13+CO13+DN13+EM13+FL13+GM13 -> 19 | Q13: =AR13+BQ13+CP13+DO13+EN13+FM13+GN13 -> 66 | R13: =AS13+BR13+CQ13+DP13+EO13+FN13+GO13 -> 85 | S13: 4 | T13: 2 | U13: =AT13+BS13+CR13+DQ13+EP13+FQ13+GR13 -> 32 | V13: =AU13+BT13+CS13+DR13+EQ13+FR13+GS13 -> 3 | W13: =AV13+BU13+CT13+DS13+ER13+FS13+GT13 -> 29 | X13: 0.25 | Y13: =AX13+BW13+CV13+DU13+ET13+FU13+GV13 -> 3 | Z13: =AY13+BX13+CW13+DV13+EU13+FV13+GW13 -> 0.184 | AA13: =AZ13+BY13+CX13+DW13+EV13+FW13+GX13 -> 29 | AB13: =AA13/N13 -> 0.012149141 | AD13: 0 | AE13: 20584 | AF13: 20584 | AG13: 30 | AH13: 48 | AI13: 343 | AJ13: 27 | AK13: 207 | AL13: 109 | AM13: 193 | AN13: 27 | AO13: 178 | AP13: 115.64045 | AQ13: 3 | AR13: 14 | AS13: 17 | AT13: 10 | AU13: 0 | AV13: 10 | AW13: 0.1 | AX13: 0 | AY13: 0 | AZ13: 10 | BA13: 0.056179775 | BC13: 0 | BD13: 6200 | BE13: 13575 | BF13: 21 | BG13: 59 | BH13: 351 | BI13: 24 | BJ13: 283 | BK13: 44 | BL13: 248 | BM13: 30 | BN13: 1348 | BO13: 10.070475 | BP13: 2 | BQ13: 7 | BR13: 9 | BS13: 3 | BT13: 0 | BU13: 3 | BV13: 0.25 | BW13: 0 | BX13: 0 | BY13: 3 | BZ13: 0.0014836795 | CB13: 25867 | CC13: 27000 | CD13: 52867 | CE13: 78 | CF13: 101 | CG13: 471 | CH13: 133 | CI13: 265 | CJ13: 73 | CK13: 182 | CL13: 62 | CM13: 346 | CN13: 152.7948 | CO13: 9 | CP13: 13 | CQ13: 22 | CR13: 6 | CS13: 2 | CT13: 4 | CU13: 0.1 | CV13: 1 | CW13: 0.038 | CX13: 5 | CY13: 0.014450867 | DA13: 5618 | DB13: 21993 | DC13: 27611 | DD13: 12 | DE13: 76 | DF13: 324 | DG13: 18 | DH13: 217 | DI13: 89 | DJ13: 147 | DK13: 18 | DL13: 217 | DM13: 127.23963 | DN13: 2 | DO13: 8 | DP13: 10 | DQ13: 2 | DR13: 0 | DS13: 2 | DT13: 0.1 | DU13: 0 | DV13: 0 | DW13: 2 | DX13: 0.0092165899 | DZ13: 0 | EA13: 13811 | EB13: 13811 | EC13: 18 | ED13: 58 | EE13: 210 | EF13: 32 | EG13: 109 | EH13: 69 | EI13: 80 | EJ13: 32 | EK13: 109 | EL13: 126.70642 | EM13: 3 | EN13: 12 | EO13: 15 | EP13: 6 | EQ13: 1 | ER13: 5 | ES13: 0.1 | ET13: 1 | EU13: 0.063 | EV13: 5 | EW13: 0.04587156 | EY13: 0 | EZ13: 16740 | FA13: 16740 | FB13: 0 | FC13: 74 | FD13: 230 | FE13: 0 | FF13: 164 | FG13: 66 | FH13: 130 | FI13: 18 | FJ13: 164 | FK13: 102.07317 | FL13: 0 | FM13: 11 | FN13: 11 | FO13: 14 | FP13: 11 | FQ13: 3 | FR13: 0 | FS13: 3 | FT13: 0.214 | FU13: 0 | FV13: 0 | FW13: 3 | FX13: 0.018292683 | FZ13: 0 | GA13: 0 | GB13: 0 | GC13: 0 | GD13: 17 | GE13: 58 | GF13: 0 | GG13: 37 | GH13: 21 | GI13: 23 | GJ13: 12 | GK13: 25 | GL13: 0 | GM13: 0 | GN13: 1 | GO13: 1 | GP13: 4 | GQ13: 2 | GR13: 2 | GS13: 0 | GT13: 2 | GU13: 0.25 | GV13: 1 | GW13: 0.083 | GX13: 1 | GY13: 0.04
A14: 10 | B14: 河源零跑 | C14: =AD14+BC14+CB14+DA14+DZ14+EY14+FZ14 -> 243673.29 | D14: =AE14+BD14+CC14+DB14+EA14+EZ14+GA14 -> 281600.38 | E14: =AF14+BE14+CD14+DC14+EB14+FA14+GB14 -> 525273.67 | F14: =AG14+BF14+CE14+DD14+EC14+FB14+GC14 -> 462 | G14: =AH14+BG14+CF14+DE14+ED14+FC14+GD14 -> 600 | H14: =AI14+BH14+CG14+DF14+EE14+FD14+GE14 -> 6538 | I14: =AJ14+BI14+CH14+DG14+EF14+FE14+GF14 -> 2621 | J14: =AK14+BJ14+CI14+DH14+EG14+FF14+GG14 -> 3506 | ... N14: =AO14+BN14+CM14+DL14+EK14+FJ14+GK14 -> 5930 | O14: =E14/N14 -> 88.579034 | P14: =AQ14+BP14+CO14+DN14+EM14+FL14+GM14 -> 380 | Q14: =AR14+BQ14+CP14+DO14+EN14+FM14+GN14 -> 222 | R14: =AS14+BR14+CQ14+DP14+EO14+FN14+GO14 -> 602 | S14: 50 | T14: 9 | U14: =AT14+BS14+CR14+DQ14+EP14+FQ14+GR14 -> 122 | V14: =AU14+BT14+CS14+DR14+EQ14+FR14+GS14 -> 87 | W14: =AV14+BU14+CT14+DS14+ER14+FS14+GT14 -> 35 | X14: 0.321 | Y14: =AX14+BW14+CV14+DU14+ET14+FU14+GV14 -> 0 | Z14: =AY14+BX14+CW14+DV14+EU14+FV14+GW14 -> 0.2 | AA14: =AZ14+BY14+CX14+DW14+EV14+FW14+GX14 -> 122 | AB14: =AA14/N14 -> 0.020573356 | AC14: 122 | AD14: 30084.76 | AE14: 26868.5 | AF14: 56953.26 | AG14: 70 | AH14: 66 | AI14: 467 | AJ14: 223 | AK14: 242 | AL14: 2 | AM14: 347 | AN14: 61 | AO14: 406 | AP14: 140.27897 | AQ14: 70 | AR14: 29 | AS14: 99 | AT14: 19 | AU14: 15 | AV14: 4 | AW14: 0.1 | AX14: 0 | AY14: 0 | AZ14: 19 | BA14: 0.034482759 | BB14: 82 | BC14: 25735.83 | BD14: 31915.64 | BE14: 57651.47 | BF14: 61 | BG14: 52 | BH14: 671 | BI14: 261 | BJ14: 374 | BK14: 36 | BL14: 523 | BM14: 75 | BN14: 634 | BO14: 90.932918 | BP14: 32 | BQ14: 35 | BR14: 67 | BS14: 5 | BT14: 4 | BU14: 1 | BV14: 0.22 | BW14: 0 | BX14: 0 | BY14: 5 | BZ14: 0.0078864353 | CA14: 96 | CB14: 47225.01 | CC14: 44540.9 | CD14: 91765.91 | CE14: 83 | CF14: 91 | CG14: 1074 | CH14: 498 | CI14: 540 | CJ14: 45 | CK14: 959 | CL14: 120 | CM14: 1005 | CN14: 91.309363 | CO14: 55 | CP14: 36 | CQ14: 91 | CR14: 21 | CS14: 14 | CT14: 7 | CU14: 0.102 | CV14: 0 | CW14: 0 | CX14: 21 | CY14: 0.020895522 | CZ14: 25 | DA14: 48197.81 | DB14: 16723.67 | DC14: 64921.48 | DD14: 75 | DE14: 84 | DF14: 840 | DG14: 603 | DH14: 183 | DI14: 54 | DJ14: 732 | DK14: 59 | DL14: 779 | DM14: 83.339512 | DN14: 80 | DO14: 47 | DP14: 127 | DQ14: 22 | DR14: 18 | DS14: 4 | DT14: 0.169 | DU14: 0 | DV14: 0 | DW14: 22 | DX14: 0.028241335 | DY14: 69 | DZ14: 43550.86 | EA14: 76139.35 | EB14: 119690.21 | EC14: 66 | ED14: 91 | EE14: 1537 | EF14: 479 | EG14: 953 | EH14: 105 | EI14: 1474 | EJ14: 129 | EK14: 1398 | EL14: 85.615315 | EM14: 54 | EN14: 35 | EO14: 89 | EP14: 25 | EQ14: 18 | ER14: 7 | ES14: 0.185 | ET14: 0 | EU14: 0.2 | EV14: 25 | EW14: 0.01788269 | EX14: 12 | EY14: 36624.52 | EZ14: 60099.82 | FA14: 96724.34 | FB14: 71 | FC14: 151 | FD14: 1391 | FE14: 412 | FF14: 855 | FG14: 124 | FH14: 1305 | FI14: 140 | FJ14: 1265 | FK14: 76.461929 | FL14: 61 | FM14: 20 | FN14: 81 | FO14: 102 | FP14: 20 | FQ14: 20 | FR14: 12 | FS14: 8 | FT14: 0.196 | FU14: 0 | FV14: 0 | FW14: 20 | FX14: 0.015810277 | FY14: 20 | FZ14: 12254.5 | GA14: 25312.5 | GB14: 37567 | GC14: 36 | GD14: 65 | GE14: 558 | GF14: 145 | GG14: 359 | GH14: 54 | GI14: 443 | GJ14: 66 | GK14: 443 | GL14: 84.801354 | GM14: 28 | GN14: 20 | GO14: 48 | GP14: 50 | GQ14: 9 | GR14: 10 | GS14: 6 | GT14: 4 | GU14: 0.321 | GV14: 0 | GW14: 0 | GX14: 10 | GY14: 0.022573363 | GZ14: 122
A15: 11 | B15: 汕头零跑 | C15: =AD15+BC15+CB15+DA15+DZ15+EY15+FZ15 -> 193560.67 | D15: =AE15+BD15+CC15+DB15+EA15+EZ15+GA15 -> 288808.13 | E15: =AF15+BE15+CD15+DC15+EB15+FA15+GB15 -> 482368.8 | F15: =AG15+BF15+CE15+DD15+EC15+FB15+GC15 -> 606 | G15: =AH15+BG15+CF15+DE15+ED15+FC15+GD15 -> 668 | H15: =AI15+BH15+CG15+DF15+EE15+FD15+GE15 -> 7545 | I15: =AJ15+BI15+CH15+DG15+EF15+FE15+GF15 -> 3618 | J15: =AK15+BJ15+CI15+DH15+EG15+FF15+GG15 -> 3816 | ... N15: =AO15+BN15+CM15+DL15+EK15+FJ15+GK15 -> 6368 | O15: =E15/N15 -> 75.748869 | P15: =AQ15+BP15+CO15+DN15+EM15+FL15+GM15 -> 325 | Q15: =AR15+BQ15+CP15+DO15+EN15+FM15+GN15 -> 204 | R15: =AS15+BR15+CQ15+DP15+EO15+FN15+GO15 -> 529 | S15: 42 | T15: 11 | U15: =AT15+BS15+CR15+DQ15+EP15+FQ15+GR15 -> 143 | V15: =AU15+BT15+CS15+DR15+EQ15+FR15+GS15 -> 103 | W15: =AV15+BU15+CT15+DS15+ER15+FS15+GT15 -> 40 | X15: 0.25 | Y15: =AX15+BW15+CV15+DU15+ET15+FU15+GV15 -> 6 | Z15: =AY15+BX15+CW15+DV15+EU15+FV15+GW15 -> 0.064 | AA15: =AZ15+BY15+CX15+DW15+EV15+FW15+GX15 -> 137 | AB15: =AA15/N15 -> 0.021513819 | AC15: 38 | AD15: 34422 | AE15: 35152 | AF15: 69574 | AG15: 60 | AH15: 80 | AI15: 593 | AJ15: 314 | AK15: 279 | AL15: 0 | AM15: 505 | AN15: 56 | AO15: 537 | AP15: 129.56052 | AQ15: 38 | AR15: 16 | AS15: 54 | AT15: 12 | AU15: 9 | AV15: 3 | AW15: 0.17 | AX15: 0 | AY15: 0 | AZ15: 12 | BA15: 0.020484171 | BB15: 140 | BC15: 9577.67 | BD15: 20477.13 | BE15: 30054.8 | BF15: 58 | BG15: 88 | BH15: 461 | BI15: 227 | BJ15: 234 | BK15: 0 | BL15: 385 | BM15: 124 | BN15: 337 | BO15: 89.183383 | BP15: 23 | BQ15: 24 | BR15: 47 | BS15: 11 | BT15: 5 | BU15: 6 | BV15: 0.33 | BW15: 0 | BX15: 0 | BY15: 11 | BZ15: 0.03264095 | CA15: 163 | CB15: 25033 | CC15: 45445 | CD15: 70478 | CE15: 89 | CF15: 99 | CG15: 1200 | CH15: 514 | CI15: 686 | CJ15: 0 | CK15: 1080 | CL15: 254 | CM15: 946 | CN15: 74.501057 | CO15: 55 | CP15: 37 | CQ15: 92 | CR15: 24 | CS15: 14 | CT15: 10 | CU15: 0.2 | CV15: 2 | CW15: 0.017 | CX15: 22 | CY15: 0.023255814 | CZ15: 10 | DA15: 36306 | DB15: 23409 | DC15: 59715 | DD15: 120 | DE15: 119 | DF15: 1337 | DG15: 893 | DH15: 432 | DI15: 12 | DJ15: 1185 | DK15: 371 | DL15: 954 | DM15: 62.59434 | DN15: 74 | DO15: 46 | DP15: 120 | DQ15: 35 | DR15: 26 | DS15: 9 | DT15: 0.2 | DU15: 3 | DV15: 0.035 | DW15: 32 | DX15: 0.033542977 | DY15: 39 | DZ15: 33880 | EA15: 78339 | EB15: 112219 | EC15: 111 | ED15: 116 | EE15: 1860 | EF15: 708 | EG15: 1094 | EH15: 58 | EI15: 1740 | EJ15: 187 | EK15: 1676 | EL15: 66.956444 | EM15: 54 | EN15: 38 | EO15: 92 | EP15: 27 | EQ15: 20 | ER15: 7 | ES15: 0.2 | ET15: 1 | EU15: 0.012 | EV15: 26 | EW15: 0.015513126 | EX15: 10 | EY15: 39507 | EZ15: 60516 | FA15: 100023 | FB15: 116 | FC15: 106 | FD15: 1548 | FE15: 734 | FF15: 786 | FG15: 28 | FH15: 1433 | FI15: 176 | FJ15: 1393 | FK15: 71.80402 | FL15: 56 | FM15: 35 | FN15: 91 | FO15: 111 | FP15: 26 | FQ15: 23 | FR15: 19 | FS15: 4 | FT15: 0.21 | FU15: 0 | FV15: 0 | FW15: 23 | FX15: 0.016511127 | FY15: 15 | FZ15: 14835 | GA15: 25470 | GB15: 40305 | GC15: 52 | GD15: 60 | GE15: 546 | GF15: 228 | GG15: 305 | GH15: 13 | GI15: 501 | GJ15: 16 | GK15: 525 | GL15: 76.771429 | GM15: 25 | GN15: 8 | GO15: 33 | GP15: 42 | GQ15: 11 | GR15: 11 | GS15: 10 | GT15: 1 | GU15: 0.25 | GV15: 0 | GW15: 0 | GX15: 11 | GY15: 0.020952381 | GZ15: 38
A16: 12 | B16: 清远港鸿 | C16: =AD16+BC16+CB16+DA16+DZ16+EY16+FZ16 -> 101387.76 | D16: =AE16+BD16+CC16+DB16+EA16+EZ16+GA16 -> 218048.59 | E16: =AF16+BE16+CD16+DC16+EB16+FA16+GB16 -> 309917.65 | F16: =AG16+BF16+CE16+DD16+EC16+FB16+GC16 -> 494 | G16: =AH16+BG16+CF16+DE16+ED16+FC16+GD16 -> 707 | H16: =AI16+BH16+CG16+DF16+EE16+FD16+GE16 -> 2655 | I16: =AJ16+BI16+CH16+DG16+EF16+FE16+GF16 -> 791 | J16: =AK16+BJ16+CI16+DH16+EG16+FF16+GG16 -> 1390 | ... N16: =AO16+BN16+CM16+DL16+EK16+FJ16+GK16 -> 2120 | O16: =E16/N16 -> 146.18757 | P16: =AQ16+BP16+CO16+DN16+EM16+FL16+GM16 -> 116 | Q16: =AR16+BQ16+CP16+DO16+EN16+FM16+GN16 -> 105 | R16: =AS16+BR16+CQ16+DP16+EO16+FN16+GO16 -> 221 | S16: 20 | T16: 2 | U16: =AT16+BS16+CR16+DQ16+EP16+FQ16+GR16 -> 44 | V16: =AU16+BT16+CS16+DR16+EQ16+FR16+GS16 -> 25 | W16: =AV16+BU16+CT16+DS16+ER16+FS16+GT16 -> 19 | X16: 0.1 | Y16: =AX16+BW16+CV16+DU16+ET16+FU16+GV16 -> 3 | Z16: =AY16+BX16+CW16+DV16+EU16+FV16+GW16 -> 0.147 | AA16: =AZ16+BY16+CX16+DW16+EV16+FW16+GX16 -> 41 | AB16: =AA16/N16 -> 0.019339623 | AC16: 572 | AD16: 20079 | AE16: 40463.31 | AF16: 60542.31 | AG16: 74 | AH16: 59 | AI16: 319 | AJ16: 126 | AK16: 168 | AL16: 25 | AM16: 341 | AN16: 50 | AO16: 269 | AP16: 225.06435 | AQ16: 34 | AR16: 20 | AS16: 54 | AT16: 11 | AU16: 6 | AV16: 5 | AW16: 0.26 | AX16: 0 | AY16: 0 | AZ16: 11 | BA16: 0.040892193 | BB16: 145 | BC16: 11168.45 | BD16: 27113.98 | BE16: 38282.43 | BF16: 56 | BG16: 54 | BH16: 282 | BI16: 61 | BJ16: 210 | BK16: 11 | BL16: 319 | BM16: 35 | BN16: 247 | BO16: 154.9896 | BP16: 7 | BQ16: 4 | BR16: 11 | BS16: 4 | BT16: 3 | BU16: 1 | BV16: 0.25 | BW16: 0 | BX16: 0 | BY16: 4 | BZ16: 0.016194332 | CA16: 350 | CB16: 14593.79 | CC16: 30106.91 | CD16: 35182 | CE16: 66 | CF16: 110 | CG16: 338 | CH16: 154 | CI16: 240 | CJ16: 24 | CK16: 220 | CL16: 30 | CM16: 245 | CN16: 143.6 | CO16: 22 | CP16: 17 | CQ16: 39 | CR16: 13 | CS16: 8 | CT16: 5 | CU16: 0.13 | CV16: 2 | CW16: 0.105 | CX16: 11 | CY16: 0.044897959 | CZ16: 512 | DA16: 28210.01 | DB16: 56684.65 | DC16: 84894.66 | DD16: 111 | DE16: 136 | DF16: 365 | DG16: 124 | DH16: 188 | DI16: 53 | DJ16: 646 | DK16: 51 | DL16: 626 | DM16: 135.61447 | DN16: 22 | DO16: 20 | DP16: 42 | DQ16: 5 | DR16: 3 | DS16: 2 | DT16: 0.062 | DU16: 0 | DV16: 0 | DW16: 5 | DX16: 0.0079872204 | DY16: 368 | DZ16: 12641.27 | EA16: 26787.28 | EB16: 39428.55 | EC16: 89 | ED16: 118 | EE16: 569 | EF16: 128 | EG16: 280 | EH16: 161 | EI16: 290 | EJ16: 110 | EK16: 335 | EL16: 117.69716 | EM16: 13 | EN16: 14 | EO16: 27 | EP16: 5 | EQ16: 3 | ER16: 2 | ES16: 0.0884 | ET16: 0 | EU16: 0 | EV16: 5 | EW16: 0.014925373 | EX16: 433 | EY16: 10195.2 | EZ16: 29323.8 | FA16: 39519 | FB16: 71 | FC16: 187 | FD16: 555 | FE16: 169 | FF16: 235 | FG16: 151 | FH16: 216 | FI16: 96 | FJ16: 309 | FK16: 127.8932 | FL16: 17 | FM16: 25 | FN16: 42 | FO16: 48 | FP16: 5 | FQ16: 4 | FR16: 2 | FS16: 2 | FT16: 0.096 | FU16: 0 | FV16: 0 | FW16: 4 | FX16: 0.012944984 | FY16: 439 | FZ16: 4500.04 | GA16: 7568.66 | GB16: 12068.7 | GC16: 27 | GD16: 43 | GE16: 227 | GF16: 29 | GG16: 69 | GH16: 129 | GI16: 91 | GJ16: 38 | GK16: 89 | GL16: 135.60337 | GM16: 1 | GN16: 5 | GO16: 6 | GP16: 20 | GQ16: 2 | GR16: 2 | GS16: 0 | GT16: 2 | GU16: 0.1 | GV16: 1 | GW16: 0.042 | GX16: 1 | GY16: 0.011235955 | GZ16: 572
A17: 13 | B17: 从化零跑 | C17: =AD17+BC17+CB17+DA17+DZ17+EY17+FZ17 -> 105830.25 | D17: =AE17+BD17+CC17+DB17+EA17+EZ17+GA17 -> 99526.22 | E17: =AF17+BE17+CD17+DC17+EB17+FA17+GB17 -> 205356.47 | F17: =AG17+BF17+CE17+DD17+EC17+FB17+GC17 -> 313 | G17: =AH17+BG17+CF17+DE17+ED17+FC17+GD17 -> 790 | H17: =AI17+BH17+CG17+DF17+EE17+FD17+GE17 -> 3253 | I17: =AJ17+BI17+CH17+DG17+EF17+FE17+GF17 -> 1876 | J17: =AK17+BJ17+CI17+DH17+EG17+FF17+GG17 -> 1227 | ... N17: =AO17+BN17+CM17+DL17+EK17+FJ17+GK17 -> 3106 | O17: =E17/N17 -> 66.116056 | P17: =AQ17+BP17+CO17+DN17+EM17+FL17+GM17 -> 62 | Q17: =AR17+BQ17+CP17+DO17+EN17+FM17+GN17 -> 10 | R17: =AS17+BR17+CQ17+DP17+EO17+FN17+GO17 -> 72 | S17: 1 | T17: 7 | U17: =AT17+BS17+CR17+DQ17+EP17+FQ17+GR17 -> 28 | V17: =AU17+BT17+CS17+DR17+EQ17+FR17+GS17 -> 28 | W17: =AV17+BU17+CT17+DS17+ER17+FS17+GT17 -> 0 | X17: 0.1 | Y17: =AX17+BW17+CV17+DU17+ET17+FU17+GV17 -> 0 | Z17: =AY17+BX17+CW17+DV17+EU17+FV17+GW17 -> 0 | AA17: =AZ17+BY17+CX17+DW17+EV17+FW17+GX17 -> 28 | AB17: =AA17/N17 -> 0.00901481 | AD17: 24033.65 | AE17: 10081.54 | AF17: 34115.19 | AG17: 52 | AH17: 143 | AI17: 539 | AJ17: 402 | AK17: 100 | AL17: 37 | AM17: 491 | AN17: 0 | AO17: 511 | AP17: 66.761624 | AQ17: 1 | AR17: 0 | AS17: 1 | AT17: 4 | AU17: 4 | AV17: 0 | AW17: 0.22 | AX17: 0 | AY17: 0 | AZ17: 4 | BA17: 0.0078277886 | BB17: 517 | BC17: 8015.6 | BD17: 7805.88 | BE17: 15821.48 | BF17: 46 | BG17: 112 | BH17: 525 | BI17: 411 | BJ17: 100 | BK17: 14 | BL17: 520 | BM17: 20 | BN17: 505 | BO17: 31.329663 | BP17: 4 | BQ17: 0 | BR17: 4 | BS17: 2 | BT17: 2 | BU17: 0 | BV17: 0.18 | BW17: 0 | BX17: 0 | BY17: 2 | BZ17: 0.003960396 | CA17: 576 | CB17: 19993.07 | CC17: 7182.71 | CD17: 27175.78 | CE17: 44 | CF17: 163 | CG17: 331 | CH17: 194 | CI17: 126 | CJ17: 11 | CK17: 321 | CL17: 2 | CM17: 318 | CN17: 85.458428 | CO17: 11 | CP17: 0 | CQ17: 11 | CR17: 4 | CS17: 4 | CT17: 0 | CU17: 0.29 | CV17: 0 | CW17: 0 | CX17: 4 | CY17: 0.012578616 | CZ17: 443 | DA17: 21578.63 | DB17: 16414.82 | DC17: 37993.45 | DD17: 58 | DE17: 96 | DF17: 719 | DG17: 560 | DH17: 149 | DI17: 10 | DJ17: 713 | DK17: 4 | DL17: 713 | DM17: 53.286746 | DN17: 23 | DO17: 2 | DP17: 25 | DQ17: 11 | DR17: 11 | DS17: 0 | DT17: 0.15 | DU17: 0 | DV17: 0 | DW17: 11 | DX17: 0.01542777 | DY17: 373 | DZ17: 21349.52 | EA17: 10192.07 | EB17: 31541.59 | EC17: 52 | ED17: 142 | EE17: 431 | EF17: 222 | EG17: 178 | EH17: 31 | EI17: 423 | EJ17: 18 | EK17: 410 | EL17: 76.930707 | EM17: 16 | EN17: 3 | EO17: 19 | EP17: 4 | EQ17: 4 | ER17: 0 | ES17: 0.27 | ET17: 0 | EU17: 0 | EV17: 4 | EW17: 0.0097560976 | EX17: 416 | EY17: 8264.17 | EZ17: 31735.8 | FA17: 39999.97 | FB17: 42 | FC17: 103 | FD17: 533 | FE17: 59 | FF17: 429 | FG17: 45 | FH17: 413 | FI17: 48 | FJ17: 485 | FK17: 82.474165 | FL17: 5 | FM17: 4 | FN17: 9 | FO17: 14 | FP17: 3 | FQ17: 2 | FR17: 2 | FS17: 0 | FT17: 0.143 | FU17: 0 | FV17: 0 | FW17: 2 | FX17: 0.0041237113 | FY17: 416 | FZ17: 2595.61 | GA17: 16113.4 | GB17: 18709.01 | GC17: 19 | GD17: 31 | GE17: 175 | GF17: 28 | GG17: 145 | GH17: 2 | GI17: 125 | GJ17: 14 | GK17: 164 | GL17: 114.07933 | GM17: 2 | GN17: 1 | GO17: 3 | GP17: 1 | GQ17: 7 | GR17: 1 | GS17: 1 | GT17: 0 | GU17: 0.1 | GV17: 0 | GW17: 0 | GX17: 1 | GY17: 0.006097561
A18: 14 | B18: 清远奇晟 | C18: =AD18+BC18+CB18+DA18+DZ18+EY18+FZ18 -> 74553.97 | D18: =AE18+BD18+CC18+DB18+EA18+EZ18+GA18 -> 85130.45 | E18: =AF18+BE18+CD18+DC18+EB18+FA18+GB18 -> 159684.42 | F18: =AG18+BF18+CE18+DD18+EC18+FB18+GC18 -> 446 | G18: =AH18+BG18+CF18+DE18+ED18+FC18+GD18 -> 711 | H18: =AI18+BH18+CG18+DF18+EE18+FD18+GE18 -> 1998 | I18: =AJ18+BI18+CH18+DG18+EF18+FE18+GF18 -> 659 | J18: =AK18+BJ18+CI18+DH18+EG18+FF18+GG18 -> 891 | ... N18: =AO18+BN18+CM18+DL18+EK18+FJ18+GK18 -> 1405 | O18: =E18/N18 -> 113.65439 | P18: =AQ18+BP18+CO18+DN18+EM18+FL18+GM18 -> 66 | Q18: =AR18+BQ18+CP18+DO18+EN18+FM18+GN18 -> 62 | R18: =AS18+BR18+CQ18+DP18+EO18+FN18+GO18 -> 128 | S18: 15 | T18: 0 | U18: =AT18+BS18+CR18+DQ18+EP18+FQ18+GR18 -> 28 | V18: =AU18+BT18+CS18+DR18+EQ18+FR18+GS18 -> 12 | W18: =AV18+BU18+CT18+DS18+ER18+FS18+GT18 -> 16 | X18: 0 | Y18: =AX18+BW18+CV18+DU18+ET18+FU18+GV18 -> 0 | Z18: =AY18+BX18+CW18+DV18+EU18+FV18+GW18 -> 0 | AA18: =AZ18+BY18+CX18+DW18+EV18+FW18+GX18 -> 28 | AB18: =AA18/N18 -> 0.019928826 | AC18: 592 | AD18: 20491 | AE18: 15364 | AF18: 35855 | AG18: 76 | AH18: 72 | AI18: 260 | AJ18: 109 | AK18: 130 | AL18: 21 | AM18: 225 | AN18: 25 | AO18: 233 | AP18: 153.88412 | AQ18: 11 | AR18: 11 | AS18: 22 | AT18: 6 | AU18: 2 | AV18: 4 | AW18: 0.1 | AX18: 0 | AY18: 0 | AZ18: 6 | BA18: 0.025751073 | BB18: 402 | BC18: 7473.12 | BD18: 12064.23 | BE18: 19537.35 | BF18: 61 | BG18: 83 | BH18: 212 | BI18: 67 | BJ18: 141 | BK18: 4 | BL18: 207 | BM18: 16 | BN18: 186 | BO18: 105.03952 | BP18: 3 | BQ18: 3 | BR18: 6 | BS18: 3 | BT18: 1 | BU18: 2 | BW18: 0 | BX18: 0 | BY18: 3 | BZ18: 0.016129032 | CA18: 402 | CB18: 10552.45 | CC18: 10803.34 | CD18: 21355.79 | CE18: 63 | CF18: 91 | CG18: 225 | CH18: 103 | CI18: 116 | CJ18: 5 | CK18: 179 | CL18: 7 | CM18: 205 | CN18: 104.17459 | CO18: 6 | CP18: 5 | CQ18: 11 | CR18: 5 | CS18: 3 | CT18: 2 | CU18: 0.11 | CV18: 0 | CW18: 0 | CX18: 5 | CY18: 0.024390244 | CZ18: 522 | DA18: 10922.67 | DB18: 15314.3 | DC18: 26236.97 | DD18: 69 | DE18: 103 | DF18: 220 | DG18: 134 | DH18: 54 | DI18: 32 | DJ18: 328 | DK18: 5 | DL18: 265 | DM18: 99.007434 | DN18: 20 | DO18: 9 | DP18: 29 | DQ18: 3 | DR18: 2 | DS18: 1 | DT18: 0.067 | DU18: 0 | DV18: 0 | DW18: 3 | DX18: 0.011320755 | DY18: 621 | DZ18: 9786.12 | EA18: 10608.42 | EB18: 20394.54 | EC18: 57 | ED18: 147 | EE18: 380 | EF18: 79 | EG18: 157 | EH18: 166 | EI18: 145 | EJ18: 75 | EK18: 173 | EL18: 117.88751 | EM18: 8 | EN18: 14 | EO18: 22 | EP18: 4 | EQ18: 2 | ER18: 2 | ES18: 0.0727 | ET18: 0 | EU18: 0 | EV18: 4 | EW18: 0.023121387 | EX18: 648 | EY18: 10326.23 | EZ18: 19776.16 | FA18: 30102.39 | FB18: 84 | FC18: 160 | FD18: 498 | FE18: 115 | FF18: 233 | FG18: 150 | FH18: 216 | FI18: 60 | FJ18: 290 | FK18: 103.80134 | FL18: 16 | FM18: 17 | FN18: 33 | FO18: 38 | FP18: 4 | FQ18: 7 | FR18: 2 | FS18: 5 | FT18: 0.087 | FU18: 0 | FV18: 0 | FW18: 7 | FX18: 0.024137931 | FY18: 525 | FZ18: 5002.38 | GA18: 1200 | GB18: 6202.38 | GC18: 36 | GD18: 55 | GE18: 203 | GF18: 52 | GG18: 60 | GH18: 91 | GI18: 56 | GJ18: 24 | GK18: 53 | GL18: 117.02604 | GM18: 2 | GN18: 3 | GO18: 5 | GP18: 15 | GQ18: 0 | GR18: 0 | GS18: 0 | GT18: 0 | GU18: 0 | GV18: 0 | GW18: 0 | GX18: 0 | GY18: 0 | GZ18: 592
